Workbook

Sheet Sheet3
B3: New | E3: Market growth new cars | J3: 35
J4: 0.35
E5: RAR | J5: =J4*J3 -> 12.25
E6: Cars financed | J6: =(J5*1000)/#REF! -> #REF!
B7: B2B opportunity | E7: RAR | F7: €M | J7: =3*50% -> 1.5 | K7: =50%*4 -> 2 | M7: 50% new and 50 % used | T7: 3 | U7: 4
C8: New | E8: Cars financed | F8: €M | J8: =J7*1000/#REF! -> #REF! | K8: =K7*1000/#REF! -> #REF!
C9: Used | E9: RAR | F9: €M | J9: =3*50% -> 1.5 | K9: =50%*4 -> 2
C10: Used | E10: Cars financed | F10: €M | J10: =J9*1000/#REF! -> #REF! | K10: =K9*1000/#REF! -> #REF!
B12: D2C | C12: Total | D12: Cash loan | E12: RAR | F12: €M | J12: 2 | K12: 3
C13: New | D13: Cash loan | E13: RAR | F13: €M | J13: =15%*J12 -> 0.3 | K13: =15%*K12 -> 0.45
B14: D2C | C14: New | D14: Cash loan | E14: cars financed | F14: k# | J14: =J13*1000/#REF! -> #REF! | K14: =K13*1000/#REF! -> #REF! | M14: B2C cars
M15: B2C is new
B16: Toyota | C16: Total | D16: Auto loan | E16: RAR | F16: €M | J16: 1 | K16: 2
C17: New | D17: Auto loan | E17: RAR | F17: €M | J17: =70%*J16 -> 0.7 | K17: =70%*K16 -> 1.4
C18: New | D18: Auto loan | E18: cars financed | F18: k# | J18: =J17*1000/#REF! -> #REF! | K18: =J17*1000/#REF! -> #REF!
C19: Used | D19: Auto loan | E19: RAR | F19: €M | J19: =J16-J17 -> 0.3 | K19: =K16-K17 -> 0.6
C20: Used | D20: Auto loan | E20: cars financed | F20: k# | J20: =J19*1000/#REF! -> #REF! | K20: =K19*1000/#REF! -> #REF!
B22: Used car finacing | E22: cars financed | F22: k# | J22: =#REF! -> #REF! | K22: =J22 -> #REF!
B24: Digital presence (Car.gr + Cardom) | E24: RAR | F24: €M | J24: =#REF!+#REF! -> #REF! | K24: =#REF!+#REF! -> #REF!
E25: cars financed | F25: k# | J25: =J24*1000/#REF! -> #REF! | K25: =K24*1000/#REF! -> #REF!
B27: Total | C27: New | J27: =J6+J8+J17 -> #REF! | K27: =J6+K8+K17 -> #REF! | M27: C2C is used
C28: Used | J28: =J25+J22+J20+J10 -> #REF! | K28: =K25+K22+K20+K10 -> #REF!

Sheet Business case on loan
K1: =+K9/K6 -> 0.41297664 | L1: =+L9/L6 -> 0.37109671 | M1: =+M9/M6 -> 0.38099352 | N1: =+N9/N6 -> 0.3684306
K2: =+K10/K7 -> 0.1497678 | L2: =+L10/L7 -> 0.13653813 | M2: =+M10/M7 -> 0.24747783 | N2: =+N10/N7 -> 0.24162759
D3: Total BP
D4: KPI | K4: 2024 | L4: =K4+1 -> 2025 | M4: =L4+1 -> 2026 | N4: =M4+1 -> 2027 | O4: =N4+1 -> 2028 | P4: =O4+1 -> 2029 | Q4: =P4+1 -> 2030 | S4: Notes
Q5: Min | R5: Max
D6: Cars financed | E6: Market | F6: New | G6: Auto loan | J6: k# | K6: =(K13*10^6/K182)/1000 -> 24.666667 | L6: =(L13*10^6/L182)/1000 -> 27.274085 | M6: =(M13*10^6/M182)/1000 -> 29.749722 | N6: =(N13*10^6/N182)/1000 -> 32.103322 | O6: =(O13*10^6/O182)/1000 -> 34.343692 | P6: =(P13*10^6/P182)/1000 -> 36.478812 | Q6: =(Q13*10^6/Q182)/1000 -> 38.515927 | R6: =(R13*10^6/R182)/1000 -> 38.515927
D7: Cars financed | E7: Market | F7: Used | G7: Auto loan | J7: k# | K7: =(K14*10^6/K183)/1000 -> 21.052632 | L7: =(L14*10^6/L183)/1000 -> 23.411965 | M7: =(M14*10^6/M183)/1000 -> 25.652056 | N7: =(N14*10^6/N183)/1000 -> 27.781721 | O7: =(O14*10^6/O183)/1000 -> 29.80893 | P7: =(P14*10^6/P183)/1000 -> 31.740901 | Q7: =(Q14*10^6/Q183)/1000 -> 33.584194 | R7: =(R14*10^6/R183)/1000 -> 33.584194
D8: Cars financed | E8: Market | F8: Used | G8: Cash loan | J8: k# | K8: =(K15*10^6/K184)/1000 -> 24 | L8: =(L15*10^6/L184)/1000 -> 24.351861 | M8: =(M15*10^6/M184)/1000 -> 24.685939 | N8: =(N15*10^6/N184)/1000 -> 25.003549 | O8: =(O15*10^6/O184)/1000 -> 25.305879 | P8: =(P15*10^6/P184)/1000 -> 25.594005 | Q8: =(Q15*10^6/Q184)/1000 -> 25.868906 | R8: =(R15*10^6/R184)/1000 -> 25.868906
D9: Cars financed | E9: Eurobank | F9: New | G9: Auto loan | J9: k# | K9: 10.186757 | L9: =SUMIFS(L$41:L$88,$G$41:$G$88,$G9,$F$41:$F$88,$F9,$D$41:$D$88,$D9) -> 10.121323 | M9: =SUMIFS(M$41:M$88,$G$41:$G$88,$G9,$F$41:$F$88,$F9,$D$41:$D$88,$D9) -> 11.334451 | N9: =SUMIFS(N$41:N$88,$G$41:$G$88,$G9,$F$41:$F$88,$F9,$D$41:$D$88,$D9) -> 11.827846 | O9: =SUMIFS(O$41:O$88,$G$41:$G$88,$G9,$F$41:$F$88,$F9,$D$41:$D$88,$D9) -> 12.008141 | P9: =SUMIFS(P$41:P$88,$G$41:$G$88,$G9,$F$41:$F$88,$F9,$D$41:$D$88,$D9) -> 12.191568 | Q9: =SUMIFS(Q$41:Q$88,$G$41:$G$88,$G9,$F$41:$F$88,$F9,$D$41:$D$88,$D9) -> 12.6897 | R9: =SUMIFS(R$41:R$88,$G$41:$G$88,$G9,$F$41:$F$88,$F9,$D$41:$D$88,$D9) -> 13.40725
D10: Cars financed | E10: Eurobank | F10: Used | G10: Auto loan | J10: k# | K10: 3.1530064 | L10: =SUMIFS(L$41:L$88,$G$41:$G$88,$G10,$F$41:$F$88,$F10,$D$41:$D$88,$D10) -> 3.1966259 | M10: =SUMIFS(M$41:M$88,$G$41:$G$88,$G10,$F$41:$F$88,$F10,$D$41:$D$88,$D10) -> 6.3483151 | N10: =SUMIFS(N$41:N$88,$G$41:$G$88,$G10,$F$41:$F$88,$F10,$D$41:$D$88,$D10) -> 6.7128304 | O10: =SUMIFS(O$41:O$88,$G$41:$G$88,$G10,$F$41:$F$88,$F10,$D$41:$D$88,$D10) -> 9.1555174 | P10: =SUMIFS(P$41:P$88,$G$41:$G$88,$G10,$F$41:$F$88,$F10,$D$41:$D$88,$D10) -> 9.6804039 | Q10: =SUMIFS(Q$41:Q$88,$G$41:$G$88,$G10,$F$41:$F$88,$F10,$D$41:$D$88,$D10) -> 10.87049 | R10: =SUMIFS(R$41:R$88,$G$41:$G$88,$G10,$F$41:$F$88,$F10,$D$41:$D$88,$D10) -> 11.782047
D11: Cars financed | E11: Eurobank | F11: Used | G11: Cash loan | J11: k# | K11: 7 | L11: =SUMIFS(L$41:L$88,$G$41:$G$88,$G11,$F$41:$F$88,$F11,$D$41:$D$88,$D11) -> 7.3055584 | M11: =SUMIFS(M$41:M$88,$G$41:$G$88,$G11,$F$41:$F$88,$F11,$D$41:$D$88,$D11) -> 7.6191151 | N11: =SUMIFS(N$41:N$88,$G$41:$G$88,$G11,$F$41:$F$88,$F11,$D$41:$D$88,$D11) -> 8.2298867 | O11: =SUMIFS(O$41:O$88,$G$41:$G$88,$G11,$F$41:$F$88,$F11,$D$41:$D$88,$D11) -> 8.8440396 | P11: =SUMIFS(P$41:P$88,$G$41:$G$88,$G11,$F$41:$F$88,$F11,$D$41:$D$88,$D11) -> 9.4618054 | Q11: =SUMIFS(Q$41:Q$88,$G$41:$G$88,$G11,$F$41:$F$88,$F11,$D$41:$D$88,$D11) -> 9.8536909 | R11: =SUMIFS(R$41:R$88,$G$41:$G$88,$G11,$F$41:$F$88,$F11,$D$41:$D$88,$D11) -> 11.21134
D12: Cars financed | E12: Eurobank | F12: Total | G12: Total | J12: k# | K12: =SUM(K9:K11) -> 20.339764 | L12: =SUM(L9:L11) -> 20.623507 | M12: =SUM(M9:M11) -> 25.301882 | N12: =SUM(N9:N11) -> 26.770563 | O12: =SUM(O9:O11) -> 30.007698 | P12: =SUM(P9:P11) -> 31.333778 | Q12: =SUM(Q9:Q11) -> 33.41388 | R12: =SUM(R9:R11) -> 36.400637
D13: Loan disbursements | E13: Market | F13: New | G13: Auto loan | J13: €M | K13: 370 | L13: =K13+($R13-$K13)/($Q$41-$K$41) -> 420 | M13: =L13+($R13-$K13)/($Q$41-$K$41) -> 470 | N13: =M13+($R13-$K13)/($Q$41-$K$41) -> 520 | O13: =N13+($R13-$K13)/($Q$41-$K$41) -> 570 | P13: =O13+($R13-$K13)/($Q$41-$K$41) -> 620 | Q13: =P13+($R13-$K13)/($Q$41-$K$41) -> 670 | R13: 670
D14: Loan disbursements | E14: Market | F14: Used | G14: Auto loan | J14: €M | K14: 200 | L14: =K14+($R14-$K14)/($Q$41-$K$41) -> 228.33333 | M14: =L14+($R14-$K14)/($Q$41-$K$41) -> 256.66667 | N14: =M14+($R14-$K14)/($Q$41-$K$41) -> 285 | O14: =N14+($R14-$K14)/($Q$41-$K$41) -> 313.33333 | P14: =O14+($R14-$K14)/($Q$41-$K$41) -> 341.66667 | Q14: =P14+($R14-$K14)/($Q$41-$K$41) -> 370 | R14: 370
D15: Loan disbursements | E15: Market | F15: Used | G15: Cash loan | J15: €M | K15: 120 | L15: =K15+($R15-$K15)/($Q$41-$K$41) -> 125 | M15: =L15+($R15-$K15)/($Q$41-$K$41) -> 130 | N15: =M15+($R15-$K15)/($Q$41-$K$41) -> 135 | O15: =N15+($R15-$K15)/($Q$41-$K$41) -> 140 | P15: =O15+($R15-$K15)/($Q$41-$K$41) -> 145 | Q15: =P15+($R15-$K15)/($Q$41-$K$41) -> 150 | R15: 150
D16: Loan disbursements | E16: Eurobank | F16: New | G16: Auto loan | J16: €M | K16: =SUMIFS(K$41:K$88,$G$41:$G$88,$G16,$F$41:$F$88,$F16,$D$41:$D$88,$D16) -> 152.80136 | L16: =SUMIFS(L$41:L$88,$G$41:$G$88,$G16,$F$41:$F$88,$F16,$D$41:$D$88,$D16) -> 155.83831 | M16: =SUMIFS(M$41:M$88,$G$41:$G$88,$G16,$F$41:$F$88,$F16,$D$41:$D$88,$D16) -> 179.01846 | N16: =SUMIFS(N$41:N$88,$G$41:$G$88,$G16,$F$41:$F$88,$F16,$D$41:$D$88,$D16) -> 191.50564 | O16: =SUMIFS(O$41:O$88,$G$41:$G$88,$G16,$F$41:$F$88,$F16,$D$41:$D$88,$D16) -> 199.18696 | P16: =SUMIFS(P$41:P$88,$G$41:$G$88,$G16,$F$41:$F$88,$F16,$D$41:$D$88,$D16) -> 207.06242 | Q16: =SUMIFS(Q$41:Q$88,$G$41:$G$88,$G16,$F$41:$F$88,$F16,$D$41:$D$88,$D16) -> 220.55587 | R16: =SUMIFS(R$41:R$88,$G$41:$G$88,$G16,$F$41:$F$88,$F16,$D$41:$D$88,$D16) -> 233.2245
D17: Loan disbursements | E17: Eurobank | F17: Used | G17: Auto loan | J17: €M | K17: =SUMIFS(K$41:K$88,$G$41:$G$88,$G17,$F$41:$F$88,$F17,$D$41:$D$88,$D17) -> 29.95356 | L17: =SUMIFS(L$41:L$88,$G$41:$G$88,$G17,$F$41:$F$88,$F17,$D$41:$D$88,$D17) -> 31.13316 | M17: =SUMIFS(M$41:M$88,$G$41:$G$88,$G17,$F$41:$F$88,$F17,$D$41:$D$88,$D17) -> 63.43246 | N17: =SUMIFS(N$41:N$88,$G$41:$G$88,$G17,$F$41:$F$88,$F17,$D$41:$D$88,$D17) -> 68.73251 | O17: =SUMIFS(O$41:O$88,$G$41:$G$88,$G17,$F$41:$F$88,$F17,$D$41:$D$88,$D17) -> 96.060723 | P17: =SUMIFS(P$41:P$88,$G$41:$G$88,$G17,$F$41:$F$88,$F17,$D$41:$D$88,$D17) -> 103.97993 | Q17: =SUMIFS(Q$41:Q$88,$G$41:$G$88,$G17,$F$41:$F$88,$F17,$D$41:$D$88,$D17) -> 119.49256 | R17: =SUMIFS(R$41:R$88,$G$41:$G$88,$G17,$F$41:$F$88,$F17,$D$41:$D$88,$D17) -> 129.57171
D18: Loan disbursements | E18: Eurobank | F18: Used | G18: Cash loan | J18: €M | K18: =SUMIFS(K$41:K$88,$G$41:$G$88,$G18,$F$41:$F$88,$F18,$D$41:$D$88,$D18) -> 37 | L18: =SUMIFS(L$41:L$88,$G$41:$G$88,$G18,$F$41:$F$88,$F18,$D$41:$D$88,$D18) -> 37.5 | M18: =SUMIFS(M$41:M$88,$G$41:$G$88,$G18,$F$41:$F$88,$F18,$D$41:$D$88,$D18) -> 40.123447 | N18: =SUMIFS(N$41:N$88,$G$41:$G$88,$G18,$F$41:$F$88,$F18,$D$41:$D$88,$D18) -> 44.43508 | O18: =SUMIFS(O$41:O$88,$G$41:$G$88,$G18,$F$41:$F$88,$F18,$D$41:$D$88,$D18) -> 48.927981 | P18: =SUMIFS(P$41:P$88,$G$41:$G$88,$G18,$F$41:$F$88,$F18,$D$41:$D$88,$D18) -> 53.60481 | Q18: =SUMIFS(Q$41:Q$88,$G$41:$G$88,$G18,$F$41:$F$88,$F18,$D$41:$D$88,$D18) -> 56.351367 | R18: =SUMIFS(R$41:R$88,$G$41:$G$88,$G18,$F$41:$F$88,$F18,$D$41:$D$88,$D18) -> 64.223654
D19: Loan disbursements | E19: Eurobank | F19: Total | G19: Total | J19: €M | K19: =SUM(K16:K18) -> 219.75492 | L19: =SUM(L16:L18) -> 224.47147 | M19: =SUM(M16:M18) -> 282.57436 | N19: =SUM(N16:N18) -> 304.67323 | O19: =SUM(O16:O18) -> 344.17567 | P19: =SUM(P16:P18) -> 364.64715 | Q19: =SUM(Q16:Q18) -> 396.3998 | R19: =SUM(R16:R18) -> 427.01986
D20: Market share | E20: Eurobank | F20: New | G20: Auto loan | J20: % | K20: =K16/K13 -> 0.41297664 | L20: =L16/L13 -> 0.37104359 | M20: =M16/M13 -> 0.38089033 | N20: =N16/N13 -> 0.36828008 | O20: =O16/O13 -> 0.34945081 | P20: =P16/P13 -> 0.33397164 | Q20: =Q16/Q13 -> 0.32918787 | R20: =R16/R13 -> 0.34809627
D21: Market share | E21: Eurobank | F21: Used | G21: Auto loan | J21: % | K21: =K17/K14 -> 0.1497678 | L21: =L17/L14 -> 0.1363496 | M21: =M17/M14 -> 0.24713945 | N21: =N17/N14 -> 0.2411667 | O21: =O17/O14 -> 0.30657678 | P21: =P17/P14 -> 0.30433149 | Q21: =Q17/Q14 -> 0.32295287 | R21: =R17/R14 -> 0.35019382
D22: Market share | E22: Eurobank | F22: Used | G22: Cash loan | J22: % | K22: =K18/K15 -> 0.30833333 | L22: =L18/L15 -> 0.3 | M22: =M18/M15 -> 0.3086419 | N22: =N18/N15 -> 0.32914874 | O22: =O18/O15 -> 0.34948558 | P22: =P18/P15 -> 0.36968835 | Q22: =Q18/Q15 -> 0.37567578 | R22: =R18/R15 -> 0.42815769
D23: Market share | E23: Eurobank | F23: Total | J23: % | K23: 0.3 | L23: 0.3 | M23: 0.32985334 | N23: 0.32412046 | O23: 0.33 | P23: 0.32950044 | Q23: 0.33310908 | R23: 0.35884022
D24: RAR | E24: Eurobank | F24: New | G24: Auto loan | J24: €M | K24: =SUMIFS(K$41:K$88,$G$41:$G$88,$G24,$F$41:$F$88,$F24,$D$41:$D$88,$D24) -> 10 | L24: =SUMIFS(L$41:L$88,$G$41:$G$88,$G24,$F$41:$F$88,$F24,$D$41:$D$88,$D24) -> 10.198751 | M24: =SUMIFS(M$41:M$88,$G$41:$G$88,$G24,$F$41:$F$88,$F24,$D$41:$D$88,$D24) -> 11.715763 | N24: =SUMIFS(N$41:N$88,$G$41:$G$88,$G24,$F$41:$F$88,$F24,$D$41:$D$88,$D24) -> 12.53298 | O24: =SUMIFS(O$41:O$88,$G$41:$G$88,$G24,$F$41:$F$88,$F24,$D$41:$D$88,$D24) -> 13.03568 | P24: =SUMIFS(P$41:P$88,$G$41:$G$88,$G24,$F$41:$F$88,$F24,$D$41:$D$88,$D24) -> 13.551085 | Q24: =SUMIFS(Q$41:Q$88,$G$41:$G$88,$G24,$F$41:$F$88,$F24,$D$41:$D$88,$D24) -> 14.434157 | R24: =SUMIFS(R$41:R$88,$G$41:$G$88,$G24,$F$41:$F$88,$F24,$D$41:$D$88,$D24) -> 15.263248
D25: RAR | E25: Eurobank | F25: Used | G25: Auto loan | J25: €M | K25: =SUMIFS(K$41:K$88,$G$41:$G$88,$G25,$F$41:$F$88,$F25,$D$41:$D$88,$D25) -> 4.3 | L25: =SUMIFS(L$41:L$88,$G$41:$G$88,$G25,$F$41:$F$88,$F25,$D$41:$D$88,$D25) -> 4.583785 | M25: =SUMIFS(M$41:M$88,$G$41:$G$88,$G25,$F$41:$F$88,$F25,$D$41:$D$88,$D25) -> 8.6617233 | N25: =SUMIFS(N$41:N$88,$G$41:$G$88,$G25,$F$41:$F$88,$F25,$D$41:$D$88,$D25) -> 9.4117305 | O25: =SUMIFS(O$41:O$88,$G$41:$G$88,$G25,$F$41:$F$88,$F25,$D$41:$D$88,$D25) -> 13.29418 | P25: =SUMIFS(P$41:P$88,$G$41:$G$88,$G25,$F$41:$F$88,$F25,$D$41:$D$88,$D25) -> 14.357454 | Q25: =SUMIFS(Q$41:Q$88,$G$41:$G$88,$G25,$F$41:$F$88,$F25,$D$41:$D$88,$D25) -> 16.289561 | R25: =SUMIFS(R$41:R$88,$G$41:$G$88,$G25,$F$41:$F$88,$F25,$D$41:$D$88,$D25) -> 17.589585
D26: RAR | E26: Eurobank | F26: Used | G26: Cash loan | J26: €M | K26: =SUMIFS(K$41:K$88,$G$41:$G$88,$G26,$F$41:$F$88,$F26,$D$41:$D$88,$D26) -> 5 | L26: =SUMIFS(L$41:L$88,$G$41:$G$88,$G26,$F$41:$F$88,$F26,$D$41:$D$88,$D26) -> 5.3833333 | M26: =SUMIFS(M$41:M$88,$G$41:$G$88,$G26,$F$41:$F$88,$F26,$D$41:$D$88,$D26) -> 5.7262403 | N26: =SUMIFS(N$41:N$88,$G$41:$G$88,$G26,$F$41:$F$88,$F26,$D$41:$D$88,$D26) -> 6.3254502 | O26: =SUMIFS(O$41:O$88,$G$41:$G$88,$G26,$F$41:$F$88,$F26,$D$41:$D$88,$D26) -> 6.9486441 | P26: =SUMIFS(P$41:P$88,$G$41:$G$88,$G26,$F$41:$F$88,$F26,$D$41:$D$88,$D26) -> 7.596124 | Q26: =SUMIFS(Q$41:Q$88,$G$41:$G$88,$G26,$F$41:$F$88,$F26,$D$41:$D$88,$D26) -> 8.0769867 | R26: =SUMIFS(R$41:R$88,$G$41:$G$88,$G26,$F$41:$F$88,$F26,$D$41:$D$88,$D26) -> 9.1862227
D27: RAR | E27: Eurobank | F27: Total | G27: Total | J27: €M | K27: =SUM(K24:K26) -> 19.3 | L27: =SUM(L24:L26) -> 20.16587 | M27: =SUM(M24:M26) -> 26.103727 | N27: =SUM(N24:N26) -> 28.270161 | O27: =SUM(O24:O26) -> 33.278504 | P27: =SUM(P24:P26) -> 35.504663 | Q27: =SUM(Q24:Q26) -> 38.800705 | R27: =SUM(R24:R26) -> 42.039055
B28: Highly preliminary | D28: Opex | E28: Eurobank | F28: New | G28: Auto loan | J28: €M | K28: =SUMIFS(K$41:K$88,$G$41:$G$88,$G28,$F$41:$F$88,$F28,$D$41:$D$88,$D28) -> 2.9333286 | L28: =SUMIFS(L$41:L$88,$G$41:$G$88,$G28,$F$41:$F$88,$F28,$D$41:$D$88,$D28) -> 2.7536593 | M28: =SUMIFS(M$41:M$88,$G$41:$G$88,$G28,$F$41:$F$88,$F28,$D$41:$D$88,$D28) -> 2.8898855 | N28: =SUMIFS(N$41:N$88,$G$41:$G$88,$G28,$F$41:$F$88,$F28,$D$41:$D$88,$D28) -> 2.7990308 | O28: =SUMIFS(O$41:O$88,$G$41:$G$88,$G28,$F$41:$F$88,$F28,$D$41:$D$88,$D28) -> 2.607136 | P28: =SUMIFS(P$41:P$88,$G$41:$G$88,$G28,$F$41:$F$88,$F28,$D$41:$D$88,$D28) -> 2.7102169 | Q28: =SUMIFS(Q$41:Q$88,$G$41:$G$88,$G28,$F$41:$F$88,$F28,$D$41:$D$88,$D28) -> 2.8868313 | R28: =SUMIFS(R$41:R$88,$G$41:$G$88,$G28,$F$41:$F$88,$F28,$D$41:$D$88,$D28) -> 3.8158119 | S28: Considered 25-20% Opex/RAR, starting from 29% in 2024 (source ERB P&L) and gradually decreasing to 20% in 2030
B29: Highly preliminary | D29: Opex | E29: Eurobank | F29: Used | G29: Auto loan | J29: €M | K29: =SUMIFS(K$41:K$88,$G$41:$G$88,$G29,$F$41:$F$88,$F29,$D$41:$D$88,$D29) -> 0.602 | L29: =SUMIFS(L$41:L$88,$G$41:$G$88,$G29,$F$41:$F$88,$F29,$D$41:$D$88,$D29) -> 0.60505962 | M29: =SUMIFS(M$41:M$88,$G$41:$G$88,$G29,$F$41:$F$88,$F29,$D$41:$D$88,$D29) -> 1.0740537 | N29: =SUMIFS(N$41:N$88,$G$41:$G$88,$G29,$F$41:$F$88,$F29,$D$41:$D$88,$D29) -> 1.0917607 | O29: =SUMIFS(O$41:O$88,$G$41:$G$88,$G29,$F$41:$F$88,$F29,$D$41:$D$88,$D29) -> 1.4357714 | P29: =SUMIFS(P$41:P$88,$G$41:$G$88,$G29,$F$41:$F$88,$F29,$D$41:$D$88,$D29) -> 1.4357454 | Q29: =SUMIFS(Q$41:Q$88,$G$41:$G$88,$G29,$F$41:$F$88,$F29,$D$41:$D$88,$D29) -> 1.9547474 | R29: =SUMIFS(R$41:R$88,$G$41:$G$88,$G29,$F$41:$F$88,$F29,$D$41:$D$88,$D29) -> 2.6384377 | S29: Considered 10-15% Opex/RAR, starting from 15% in 2024 (source ERB P&L) and gradually decreasing to 12% in 2030
B30: Highly preliminary | D30: Opex | E30: Eurobank | F30: Used | G30: Cash loan | J30: €M | K30: =SUMIFS(K$41:K$88,$G$41:$G$88,$G30,$F$41:$F$88,$F30,$D$41:$D$88,$D30) -> 0.75 | L30: =SUMIFS(L$41:L$88,$G$41:$G$88,$G30,$F$41:$F$88,$F30,$D$41:$D$88,$D30) -> 0.8075 | M30: =SUMIFS(M$41:M$88,$G$41:$G$88,$G30,$F$41:$F$88,$F30,$D$41:$D$88,$D30) -> 0.85893604 | N30: =SUMIFS(N$41:N$88,$G$41:$G$88,$G30,$F$41:$F$88,$F30,$D$41:$D$88,$D30) -> 0.94881754 | O30: =SUMIFS(O$41:O$88,$G$41:$G$88,$G30,$F$41:$F$88,$F30,$D$41:$D$88,$D30) -> 1.0422966 | P30: =SUMIFS(P$41:P$88,$G$41:$G$88,$G30,$F$41:$F$88,$F30,$D$41:$D$88,$D30) -> 1.1394186 | Q30: =SUMIFS(Q$41:Q$88,$G$41:$G$88,$G30,$F$41:$F$88,$F30,$D$41:$D$88,$D30) -> 1.211548 | R30: =SUMIFS(R$41:R$88,$G$41:$G$88,$G30,$F$41:$F$88,$F30,$D$41:$D$88,$D30) -> 1.3779334 | S30: Considered 15% Opex/RAR - to be checked against cash loan incidence of Opex/ RAR
B31: Highly preliminary | D31: Opex | E31: Eurobank | F31: Total | G31: Total | J31: €M | K31: =SUM(K28:K30) -> 4.2853286 | L31: =SUM(L28:L30) -> 4.1662189 | M31: =SUM(M28:M30) -> 4.8228753 | N31: =SUM(N28:N30) -> 4.8396091 | O31: =SUM(O28:O30) -> 5.0852041 | P31: =SUM(P28:P30) -> 5.285381 | Q31: =SUM(Q28:Q30) -> 6.0531267 | R31: =SUM(R28:R30) -> 7.8321831
D32: PBT | E32: Eurobank | F32: New | G32: Auto loan | J32: €M | K32: =SUMIFS(K$41:K$88,$G$41:$G$88,$G32,$F$41:$F$88,$F32,$D$41:$D$88,$D32) -> 7.0666714 | L32: =SUMIFS(L$41:L$88,$G$41:$G$88,$G32,$F$41:$F$88,$F32,$D$41:$D$88,$D32) -> 7.4450921 | M32: =SUMIFS(M$41:M$88,$G$41:$G$88,$G32,$F$41:$F$88,$F32,$D$41:$D$88,$D32) -> 8.8258778 | N32: =SUMIFS(N$41:N$88,$G$41:$G$88,$G32,$F$41:$F$88,$F32,$D$41:$D$88,$D32) -> 9.7339495 | O32: =SUMIFS(O$41:O$88,$G$41:$G$88,$G32,$F$41:$F$88,$F32,$D$41:$D$88,$D32) -> 10.428544 | P32: =SUMIFS(P$41:P$88,$G$41:$G$88,$G32,$F$41:$F$88,$F32,$D$41:$D$88,$D32) -> 10.840868 | Q32: =SUMIFS(Q$41:Q$88,$G$41:$G$88,$G32,$F$41:$F$88,$F32,$D$41:$D$88,$D32) -> 11.547325 | R32: =SUMIFS(R$41:R$88,$G$41:$G$88,$G32,$F$41:$F$88,$F32,$D$41:$D$88,$D32) -> 11.447436
D33: PBT | E33: Eurobank | F33: Used | G33: Auto loan | J33: €M | K33: =SUMIFS(K$41:K$88,$G$41:$G$88,$G33,$F$41:$F$88,$F33,$D$41:$D$88,$D33) -> 3.698 | L33: =SUMIFS(L$41:L$88,$G$41:$G$88,$G33,$F$41:$F$88,$F33,$D$41:$D$88,$D33) -> 3.9787254 | M33: =SUMIFS(M$41:M$88,$G$41:$G$88,$G33,$F$41:$F$88,$F33,$D$41:$D$88,$D33) -> 7.5876696 | N33: =SUMIFS(N$41:N$88,$G$41:$G$88,$G33,$F$41:$F$88,$F33,$D$41:$D$88,$D33) -> 8.3199698 | O33: =SUMIFS(O$41:O$88,$G$41:$G$88,$G33,$F$41:$F$88,$F33,$D$41:$D$88,$D33) -> 11.858409 | P33: =SUMIFS(P$41:P$88,$G$41:$G$88,$G33,$F$41:$F$88,$F33,$D$41:$D$88,$D33) -> 12.921709 | Q33: =SUMIFS(Q$41:Q$88,$G$41:$G$88,$G33,$F$41:$F$88,$F33,$D$41:$D$88,$D33) -> 14.334814 | R33: =SUMIFS(R$41:R$88,$G$41:$G$88,$G33,$F$41:$F$88,$F33,$D$41:$D$88,$D33) -> 14.951147 | S33: =+R31/R27 -> 0.1863073
D34: PBT | E34: Eurobank | F34: Used | G34: Cash loan | J34: €M | K34: =SUMIFS(K$41:K$88,$G$41:$G$88,$G34,$F$41:$F$88,$F34,$D$41:$D$88,$D34) -> 4.25 | L34: =SUMIFS(L$41:L$88,$G$41:$G$88,$G34,$F$41:$F$88,$F34,$D$41:$D$88,$D34) -> 4.5758333 | M34: =SUMIFS(M$41:M$88,$G$41:$G$88,$G34,$F$41:$F$88,$F34,$D$41:$D$88,$D34) -> 4.8673042 | N34: =SUMIFS(N$41:N$88,$G$41:$G$88,$G34,$F$41:$F$88,$F34,$D$41:$D$88,$D34) -> 5.3766327 | O34: =SUMIFS(O$41:O$88,$G$41:$G$88,$G34,$F$41:$F$88,$F34,$D$41:$D$88,$D34) -> 5.9063475 | P34: =SUMIFS(P$41:P$88,$G$41:$G$88,$G34,$F$41:$F$88,$F34,$D$41:$D$88,$D34) -> 6.4567054 | Q34: =SUMIFS(Q$41:Q$88,$G$41:$G$88,$G34,$F$41:$F$88,$F34,$D$41:$D$88,$D34) -> 6.8654387 | R34: =SUMIFS(R$41:R$88,$G$41:$G$88,$G34,$F$41:$F$88,$F34,$D$41:$D$88,$D34) -> 7.8082893
D35: PBT | E35: Eurobank | F35: Total | G35: Total | J35: €M | K35: =SUM(K32:K34) -> 15.014671 | L35: =SUM(L32:L34) -> 15.999651 | M35: =SUM(M32:M34) -> 21.280852 | N35: =SUM(N32:N34) -> 23.430552 | O35: =SUM(O32:O34) -> 28.1933 | P35: =SUM(P32:P34) -> 30.219282 | Q35: =SUM(Q32:Q34) -> 32.747578 | R35: =SUM(R32:R34) -> 34.206872
D36: Capex | E36: Eurobank | F36: Total | G36: Total
L38: =+L13/K13-1 -> 0.13513514 | M38: =+M13/L13-1 -> 0.11904762 | N38: =+N13/M13-1 -> 0.10638298 | O38: =+O13/N13-1 -> 0.096153846
L39: =+(L14)/(K14)-1 -> 0.14166667 | M39: =+(M14)/(L14)-1 -> 0.12408759 | N39: =+(N14)/(M14)-1 -> 0.11038961 | O39: =+(O14)/(N14)-1 -> 0.099415205
D40: 2024 + baseline
D41: KPI | K41: 2024 | L41: =K41+1 -> 2025 | M41: =L41+1 -> 2026 | N41: =M41+1 -> 2027 | O41: =N41+1 -> 2028 | P41: =O41+1 -> 2029 | Q41: =P41+1 -> 2030 | S41: Notes
...

Sheet McKinsey
M1: 2024 | N1: 2025 | O1: 2026 | P1: 2027 | Q1: 2028 | T1: 2024
T2: sales | U2: loans | V2: finance penetration
I3: Market | J3: New | K3: no. of loans | L3: k# | M3: 24.666667 | N3: 27.274085 | O3: 29.749722 | P3: 32.103322 | Q3: 34.343692 | S3: new | T3: 62 | U3: 25 | V3: =+U3/T3 -> 0.40322581
G4: =135*42% -> 56.7 | I4: Market | J4: Used | K4: =+K3 -> no. of loans | L4: k# | M4: 21.052632 | N4: 23.411965 | O4: 25.652056 | P4: 27.781721 | Q4: 29.80893 | S4: used | T4: 135 | U4: 21 | V4: =+U4/T4 -> 0.15555556
S5: total | T5: =+T4+T3 -> 197 | U5: =+U4+U3 -> 46 | V5: =+U5/T5 -> 0.23350254
I6: Market | J6: New | K6: disb. Amount | L6: €M | M6: =+M3*15 -> 370 | N6: 420 | O6: 470 | P6: 520 | Q6: 570
I7: Market | J7: Used | K7: =+K6 -> disb. Amount | L7: €M | M7: =+M4*9.5 -> 200 | N7: 228.33333 | O7: 256.66667 | P7: 285 | Q7: 313.33333
M8: 2024 | N8: 2025 | O8: 2026 | P8: 2027 | Q8: 2028
I9: Market | J9: New | K9: cars sales | L9: k# | M9: =+M3/V3 -> 61.173333 | N9: 66 | O9: 71 | P9: 74 | Q9: 77
I10: Market | J10: Used | K10: =+K9 -> cars sales | L10: k# | M10: =+M4/V4 -> 135.33835 | N10: =+M10 -> 135.33835 | O10: 144 | P10: 147 | Q10: 150
I12: Market | J12: New | K12: cars sales | L12: €M | M12: =+M9*15 -> 917.6 | N12: =+N9*(15*102%) -> 1009.8 | O12: =+O9*(15*102%) -> 1086.3 | P12: =+P9*(15*102%) -> 1132.2 | Q12: =+Q9*(15*102%) -> 1178.1
I13: Market | J13: Used | K13: =+K12 -> cars sales | L13: €M | M13: =+M10*8.5 -> 1150.3759 | N13: =+N10*(8.5*102%) -> 1173.3835 | O13: =+O10*(8.5*102%) -> 1248.48 | P13: =+P10*(8.5*102%) -> 1274.49 | Q13: =+Q10*(8.5*102%) -> 1300.5
I15: =+I12 -> Market | J15: =+J9 -> New | K15: annual growth | N15: =+N12/M12-1 -> 0.10047951 | O15: =+O12/N12-1 -> 0.075757576 | P15: =+P12/O12-1 -> 0.042253521 | Q15: =+Q12/P12-1 -> 0.040540541
I16: =+I15 -> Market | J16: =+J13 -> Used | K16: annual growth | N16: =+N13/M13-1 -> 0.02 | O16: =+O13/N13-1 -> 0.064 | P16: =+P13/O13-1 -> 0.020833333 | Q16: =+Q13/P13-1 -> 0.020408163
I17: =+I16 -> Market | J17: total | K17: annual growth | N17: =+(N12+N13)/(M12+M13)-1 -> 0.05571028 | O17: =+(O12+O13)/(N12+N13)-1 -> 0.069438297 | P17: =+(P12+P13)/(O12+O13)-1 -> 0.030799476 | Q17: =+(Q12+Q13)/(P12+P13)-1 -> 0.029879212
I18: =+I16 -> Market | J18: =+J15 -> New | K18: finance penetration | M18: =+M6/M12 -> 0.40322581 | N18: =+N6/N12 -> 0.41592395 | O18: =+O6/O12 -> 0.43266133 | P18: =+P6/P12 -> 0.45928281 | Q18: =+Q6/Q12 -> 0.4838299
I19: =+I18 -> Market | J19: =+J16 -> Used | K19: finance penetration | M19: =+M7/M13 -> 0.17385621 | N19: =+N7/N13 -> 0.19459396 | O19: =+O7/O13 -> 0.20558332 | P19: =+P7/P13 -> 0.22361886 | Q19: =+Q7/Q13 -> 0.24093297
B24: Sales (€M)=Loan penetrationAuto loans (€M)​ | N24: =+N12/M12-1 -> 0.10047951 | O24: =+O12/N12-1 -> 0.075757576 | P24: =+P12/O12-1 -> 0.042253521 | Q24: =+Q12/P12-1 -> 0.040540541
B25: +2% p.a.increse on car prices | N25: =+N13/M13-1 -> 0.02 | O25: =+O13/N13-1 -> 0.064 | P25: =+P13/O13-1 -> 0.020833333 | Q25: =+Q13/P13-1 -> 0.020408163
B26: new: 40% (2024) → 41% (2025) → 42% (2026) → 43% (2027) → 44% (2028)
B27: used: 16% (2024) → 17% (2025) → 18% (2026) → 19% (2027) → 20% (2028)
N28: =+N10+N9 -> 201.33835
B29: Έτος | C29: New Sales k# | D29: Used Sales k# | N29: =+N10/N28 -> 0.67219359
B30: 2024 | C30: 61 | D30: 135
B31: 2025 | C31: 27/41% = 66 | D31: 23/17% = 135
B32: 2026 | C32: 30/42% = 71 | D32: 26/18% = 144
B33: 2027 | C33: 32/43% = 74 | D33: 28/19% = 147
B34: 2028 | C34: 34/44% = 77 | D34: 30/20% = 150

Sheet sales analysis (MRKT)
A1: Έτος | B1: Εισαγόμενα (συνολικά) | C1: ετήσια αύξηση | D1: Επιβατικά ποσοστό | E1: Επιβατικά Εισαγόμενα | F1: Επιβ. Νέα ποσοστό | G1: Επιβ. Νέα Εισαγόμενα | H1: Επιβ. Μτχ Εισαγόμενα | I1: Μεταβιβ. Επιβ. Μτχ | J1: Νέα Retail ποσοστό | K1: Νέα Retail | L1: Νέα Wholesale ποσοστό | M1: Νέα Wholesale | N1: Μτχ Retail ποσοστό | O1: Μτχ Retail | P1: Μτχ Wholesale ποσοστό | Q1: Μτχ Wholesale
A2: 2024 | B2: 243796 | D2: =+E2/B2 -> 0.56235951 | E2: 137101 | F2: =+G2/E2 -> 0.70479428 | G2: 96628 | H2: 40473 | I2: 66527 | J2: =+K2/G2 -> 0.631287 | K2: 61000 | L2: =+M2/G2 -> 0.368713 | M2: 35628 | N2: =+O2/(H2+I2) -> 0.9 | O2: 96300 | P2: =+Q2/(H2+I2) -> 0.1 | Q2: 10700
A3: 2025 | B3: =+B2*C3+100%+B2 -> 248672.92 | C3: 0.02 | D3: 0.56235951 | E3: =+D3*B3 -> 139843.58 | F3: 0.70479428 | G3: =+F3*E3 -> 98560.956 | H3: =+E3-G3 -> 41282.626 | I3: 69000 | J3: =+K3/G3 -> 0.63919834 | K3: 63000 | L3: =+M3/G3 -> 0.3764168 | M3: 37100 | N3: =+O3/(H3+I3) -> 0.89315973 | O3: 98500 | P3: =+Q3/(H3+I3) -> 0.09520992 | Q3: 10500
A4: 2026 | B4: =+B3*C4+100%+B3 -> 253896.05 | C4: 0.021 | D4: 0.56235951 | E4: =+D4*B4 -> 142780.86 | F4: 0.70479428 | G4: =+F4*E4 -> 100631.13 | H4: =+E4-G4 -> 42149.727 | I4: 71500 | J4: =+K4/G4 -> 0.65089201 | K4: 65500 | L4: =+M4/G4 -> 0.38854775 | M4: 39100 | N4: =+O4/(H4+I4) -> 0.8860558 | O4: 100700 | P4: =+Q4/(H4+I4) -> 0.088869549 | Q4: 10100
A5: 2027 | B5: =+B4*C5+100%+B4 -> 259482.76 | C5: 0.022 | D5: 0.56235951 | E5: =+D5*B5 -> 145922.6 | F5: 0.70479428 | G5: =+F5*E5 -> 102845.41 | H5: =+E5-G5 -> 43077.187 | I5: 74000 | J5: =+K5/G5 -> 0.66118651 | K5: 68000 | L5: =+M5/G5 -> 0.4025459 | M5: 41400 | N5: =+O5/(H5+I5) -> 0.87890735 | O5: 102900 | P5: =+Q5/(H5+I5) -> 0.084559599 | Q5: 9900
A6: 2027 | B6: =+B5*C6+100%+B5 -> 265451.87 | C6: 0.023 | D6: 0.56235951 | E6: =+D6*B6 -> 149279.38 | F6: 0.70479428 | G6: =+F6*E6 -> 105211.25 | H6: =+E6-G6 -> 44068.128 | I6: 74000 | J6: =+K6/G6 -> 0.64631869 | K6: 68000 | L6: =+M6/G6 -> 0.39349402 | M6: 41400 | N6: =+O6/(H6+I6) -> 0.87153071 | O6: 102900 | P6: =+Q6/(H6+I6) -> 0.083849893 | Q6: 9900
A10: Notes:
A11: actual data

Sheet Disb. analysis (MRKT)
A1: Έτος | B1: Νέα πωλήσεις | C1: Finance contribution new | D1: Νέα δάνεια | E1: μέσο ποσό δανείου νέα | F1: Νέα Εκταμιεύσεις (€) | G1: Μτχ πωλήσεις | H1: Finance contribution used | I1: Μτχ δάνεια (k) | J1: μέσο ποσό δανείου Μτχ | K1: Μτχ Εκταμιεύσεις (€) | L1: Σύνολο Εκταμιεύσεις (€)
A2: 2024 | B2: =+'sales analysis (MRKT)'!K2 -> 61000 | C2: =+D2/B2 -> 0.40983607 | D2: 25000 | E2: 15000 | F2: =+E2*D2 -> 375000000 | G2: =+'sales analysis (MRKT)'!O2 -> 96300 | H2: =+I2/G2 -> 0.21806854 | I2: 21000 | J2: 8600 | K2: =+J2*I2 -> 180600000 | L2: =+K2+F2 -> 555600000
A3: 2025 | B3: =+'sales analysis (MRKT)'!K3 -> 63000 | C3: =+C2 -> 0.40983607 | D3: =+C3*B3 -> 25819.672 | E3: =+E2*102% -> 15300 | F3: =+E3*D3 -> 3.9504098e+08 | G3: =+'sales analysis (MRKT)'!O3 -> 98500 | H3: =+H2 -> 0.21806854 | I3: =+H3*G3 -> 21479.751 | J3: 8600 | K3: =+J3*I3 -> 1.8472586e+08 | L3: =+K3+F3 -> 5.7976684e+08
A4: 2026 | B4: =+'sales analysis (MRKT)'!K4 -> 65500 | C4: =+C3 -> 0.40983607 | D4: 30000 | E4: =+E3*102% -> 15606 | F4: =+E4*D4 -> 468180000 | G4: =+'sales analysis (MRKT)'!O4 -> 100700 | H4: =+H3 -> 0.21806854 | I4: =+H4*G4 -> 21959.502 | J4: 8600 | K4: =+J4*I4 -> 1.8885171e+08 | L4: =+K4+F4 -> 6.5703171e+08
A5: 2027 | B5: =+'sales analysis (MRKT)'!K5 -> 68000 | C5: =+C4 -> 0.40983607 | D5: 32000 | E5: =+E4*102% -> 15918.12 | F5: =+E5*D5 -> 509379840 | G5: =+'sales analysis (MRKT)'!O5 -> 102900 | H5: =+H4 -> 0.21806854 | I5: =+H5*G5 -> 22439.252 | J5: 8600 | K5: =+J5*I5 -> 1.9297757e+08 | L5: =+K5+F5 -> 7.0235741e+08
A6: 2028 | B6: =+'sales analysis (MRKT)'!K6 -> 68000 | C6: =+C5 -> 0.40983607 | D6: 34000 | E6: =+E5*102% -> 16236.482 | F6: =+E6*D6 -> 5.520404e+08 | G6: =+'sales analysis (MRKT)'!O6 -> 102900 | H6: =+H5 -> 0.21806854 | I6: =+H6*G6 -> 22439.252 | J6: 8600 | K6: =+J6*I6 -> 1.9297757e+08 | L6: =+K6+F6 -> 7.4501797e+08
A10: Notes:
A11: 2% annual infation

Sheet Disb. analysis (S.Βanks)
A1: Έτος | B1: Νέα Εκταμιεύσεις (€) | C1: Μτχ Εκταμιεύσεις (€) | D1: Σύνολο Εκταμιεύσεις (€) | E1: S. Banks market share | F1: Σύνολο Εκταμιεύσεις (€) S.Banks | G1: Νέα Εκταμιεύσεις (€) | H1: Μτχ Εκταμιεύσεις (€) | I1: Σύνολο Εκταμιεύσεις (€) | J1: S.Banks portion on total market
A2: 2024 | B2: 375000000 | C2: 180600000 | D2: 555600000 | E2: =+F2/D2 -> 0.7649388 | F2: 425000000 | G2: =+F2*(B2/D2) -> 2.8685205e+08 | H2: =+F2*(C2/D2) -> 1.3814795e+08 | I2: =+H2+G2 -> 425000000 | J2: =+I2/'Disb. analysis (MRKT)'!L2 -> 0.7649388
A3: 2025 | B3: 3.9504098e+08 | C3: 1.8472586e+08 | D3: 5.7976684e+08 | E3: =+E2 -> 0.7649388 | F3: =+E3*D3 -> 4.4348615e+08 | G3: =+F3*(B3/D3) -> 3.0218218e+08 | H3: =+F3*(C3/D3) -> 1.4130398e+08 | I3: =+H3+G3 -> 4.4348615e+08 | J3: =+I3/'Disb. analysis (MRKT)'!L3 -> 0.7649388
A4: 2026 | B4: 468180000 | C4: 1.8885171e+08 | D4: 6.5703171e+08 | E4: =+E3 -> 0.7649388 | F4: =+E4*D4 -> 5.0258905e+08 | G4: =+F4*(B4/D4) -> 3.5812905e+08 | H4: =+F4*(C4/D4) -> 1.4446e+08 | I4: =+H4+G4 -> 5.0258905e+08 | J4: =+I4/'Disb. analysis (MRKT)'!L4 -> 0.7649388
A5: 2027 | B5: 509379840 | C5: 1.9297757e+08 | D5: 7.0235741e+08 | E5: =+E4 -> 0.7649388 | F5: =+E5*D5 -> 5.3726044e+08 | G5: =+F5*(B5/D5) -> 3.8964441e+08 | H5: =+F5*(C5/D5) -> 1.4761603e+08 | I5: =+H5+G5 -> 5.3726044e+08 | J5: =+I5/'Disb. analysis (MRKT)'!L5 -> 0.7649388
A6: 2028 | B6: 5.520404e+08 | C6: 1.9297757e+08 | D6: 7.4501797e+08 | E6: =+E5 -> 0.7649388 | F6: =+E6*D6 -> 5.6989316e+08 | G6: =+F6*(B6/D6) -> 4.2227713e+08 | H6: =+F6*(C6/D6) -> 1.4761603e+08 | I6: =+H6+G6 -> 5.6989316e+08 | J6: =+I6/'Disb. analysis (MRKT)'!L6 -> 0.7649388
A10: Notes:

Sheet Disb. analysis (EUROBANK)
A1: Έτος | B1: Εκταμιεύσεις Eurobank new | C1: Εκταμιεύσεις Eurobank used | D1: Market share new total market | E1: Market share used total market | F1: Market share auto total market | G1: Market share new S. Banks market | H1: Market share used S. Banks market | I1: Market share auto S. Banks market
A2: 2024 | B2: 128675000 | C2: 28253000 | D2: =+B2/'Disb. analysis (MRKT)'!F2 -> 0.34313333 | E2: =+C2/'Disb. analysis (MRKT)'!K2 -> 0.15643965 | F2: =+(B2+C2)/'Disb. analysis (MRKT)'!L2 -> 0.2824478 | G2: =+B2/'Disb. analysis (S.Βanks)'!G2 -> 0.44857619 | H2: =+C2/'Disb. analysis (S.Βanks)'!H2 -> 0.20451263 | I2: =+(B2+C2)/'Disb. analysis (S.Βanks)'!I2 -> 0.36924235
A3: 2025 | B3: 119167000 | C3: 21588750 | D3: =+B3/'Disb. analysis (MRKT)'!F3 -> 0.30165731 | E3: =+C3/'Disb. analysis (MRKT)'!K3 -> 0.11686913 | F3: =+(B3+C3)/'Disb. analysis (MRKT)'!L3 -> 0.24277992 | G3: =+B3/'Disb. analysis (S.Βanks)'!G3 -> 0.39435483 | H3: =+C3/'Disb. analysis (S.Βanks)'!H3 -> 0.15278233 | I3: =+(B3+C3)/'Disb. analysis (S.Βanks)'!I3 -> 0.31738477
A4: 2026 | B4: 124500000 | C4: 20400000 | D4: =+B4/'Disb. analysis (MRKT)'!F4 -> 0.26592336 | E4: =+C4/'Disb. analysis (MRKT)'!K4 -> 0.10802126 | F4: =+(B4+C4)/'Disb. analysis (MRKT)'!L4 -> 0.2205373 | G4: =+B4/'Disb. analysis (S.Βanks)'!G4 -> 0.34764005 | H4: =+C4/'Disb. analysis (S.Βanks)'!H4 -> 0.14121556 | I4: =+(B4+C4)/'Disb. analysis (S.Βanks)'!I4 -> 0.28830711
A5: 2027 | B5: 128000000 | C5: 21000000 | D5: =+B5/'Disb. analysis (MRKT)'!F5 -> 0.25128596 | E5: =+C5/'Disb. analysis (MRKT)'!K5 -> 0.10882094 | F5: =+(B5+C5)/'Disb. analysis (MRKT)'!L5 -> 0.2121427 | G5: =+B5/'Disb. analysis (S.Βanks)'!G5 -> 0.32850465 | H5: =+C5/'Disb. analysis (S.Βanks)'!H5 -> 0.14226097 | I5: =+(B5+C5)/'Disb. analysis (S.Βanks)'!I5 -> 0.27733291
A6: 2028 | B6: 130000000 | C6: 23000000 | D6: =+B6/'Disb. analysis (MRKT)'!F6 -> 0.23549001 | E6: =+C6/'Disb. analysis (MRKT)'!K6 -> 0.11918484 | F6: =+(B6+C6)/'Disb. analysis (MRKT)'!L6 -> 0.20536417 | G6: =+B6/'Disb. analysis (S.Βanks)'!G6 -> 0.30785471 | H6: =+C6/'Disb. analysis (S.Βanks)'!H6 -> 0.15580963 | I6: =+(B6+C6)/'Disb. analysis (S.Βanks)'!I6 -> 0.26847138
A10: Notes:
A11: actual data

Sheet B2B financing market
B2: 1. Avg. yearly stock, by segment
D3: 2024 | E3: 2030 | F3: 2030 | J3: 2030
B4: Segment | C4: Car type | D4: Car sold to end customers, yearly | E4: Car sold to end customers, yearly | F4: Car sold to end customers, monthly | G4: Avg. stock Rotation, per year | H4: Avg. Yearly stock, k# | I4: Financing penetration, % | J4: Car volumes financed, k# | K4: Yearly target for retail, % | L4: Yearly target for SB, % | M4: Yearly target for retail, #k | N4: Yearly target for retail, #k | O4: Notes
B5: in k#
A6: =B6&C6 -> DealerNew Auto | B6: Dealer | C6: New Auto | D6: 62 | E6: 74 | F6: =E6/12 -> 6.1666667 | G6: =360/60 -> 6 | H6: =E6/G6 -> 12.333333 | I6: 0.9 | J6: =(E6)*I6 -> 66.6 | K6: 1 | M6: =J6*K6 -> 66.6 | N6: =K6*L6 -> 0 | O6: Assuming stable inventory; stock rotation: 365/days supply
A7: =B7&C7 -> DealerUsed Auto | B7: Dealer | C7: Used Auto | D7: 68 | E7: 90 | F7: =E7/12 -> 7.5 | G7: =365/45 -> 8.1111111 | H7: =E7/G7 -> 11.09589 | I7: 0.9 | J7: =(E7)*I7 -> 81 | K7: 1 | M7: =J7*K7 -> 81 | N7: =K7*L7 -> 0 | O7: Assuming stable inventory; stock rotation: 365/days supply
A8: =B8&C8 -> Independent dealersNew Auto | B8: Independent dealers | C8: New Auto | D8: =85%*D6 -> 52.7 | E8: =85%*E6 -> 62.9 | G8: =360/60 -> 6 | H8: =E8/G8 -> 10.483333 | I8: 0.9 | J8: =(E8)*I8 -> 56.61
A9: =B9&C9 -> Independent dealersUsed Auto | B9: Independent dealers | C9: Used Auto | D9: =85%*D7 -> 57.8 | E9: =85%*E7 -> 76.5 | G9: =365/45 -> 8.1111111 | H9: =E9/G9 -> 9.4315068 | I9: 0.9 | J9: =(E9)*I9 -> 68.85
A10: =B10&C10 -> Dealers with OEMs captivesNew Auto | B10: Dealers with OEMs captives | C10: New Auto | D10: =D6-D8 -> 9.3 | E10: =E6-E8 -> 11.1 | G10: =360/60 -> 6 | H10: =E10/G10 -> 1.85 | I10: 0.9 | J10: =(E10)*I10 -> 9.99
A11: =B11&C11 -> Dealers with OEMs captivesUsed Auto | B11: Dealers with OEMs captives | C11: Used Auto | D11: =D7-D9 -> 10.2 | E11: =E7-E9 -> 13.5 | G11: =365/45 -> 8.1111111 | H11: =E11/G11 -> 1.6643836 | I11: 0.9 | J11: =(E11)*I11 -> 12.15
A12: =B12&C12 -> LeaseCosNew Auto | B12: LeaseCos | C12: New Auto | D12: 45 | E12: 54 | F12: =E12/12 -> 4.5 | I12: 0.85 | J12: =(E12)*I12 -> 45.9 | L12: 0.2 | M12: =J12*K12 -> 0 | N12: =K12*L12 -> 0 | O12: ERB Leasing
A13: =B13&C13 -> LeaseCosUsed Auto | B13: LeaseCos | C13: Used Auto | D13: 0 | E13: 0 | F13: =E13/12 -> 0 | I13: 0.85 | J13: =(E13)*I13 -> 0 | L13: 0.2 | M13: =J13*K13 -> 0 | N13: =K13*L13 -> 0 | O13: ERB Leasing
A14: =B14&C14 -> RACNew Auto | B14: RAC | C14: New Auto | D14: 26 | E14: 31 | F14: =E14/12 -> 2.5833333 | I14: 0.8 | J14: =(E14)*I14 -> 24.8 | L14: 0.3 | M14: =J14*K14 -> 0 | N14: =K14*L14 -> 0
A15: =B15&C15 -> RACUsed Auto | B15: RAC | C15: Used Auto | D15: 14 | E15: 16 | F15: =E15/12 -> 1.3333333 | I15: 0.8 | J15: =(E15)*I15 -> 12.8 | L15: 0.3 | M15: =J15*K15 -> 0 | N15: =K15*L15 -> 0
A16: small | B16: RAC | C16: New Auto | D16: =ROUND(30%*D14,0) -> 8 | F16: =E16/12 -> 0 | G16: =360/30 -> 12 | I16: 0.35 | J16: =(E16)*I16 -> 0 | M16: =J16*K16 -> 0 | N16: =K16*L16 -> 0
A17: small | B17: RAC | C17: Used Auto | D17: =ROUND(30%*D15,0) -> 4 | F17: =E17/12 -> 0 | G17: =360/30 -> 12 | I17: 0.35 | J17: =(E17)*I17 -> 0 | M17: =J17*K17 -> 0 | N17: =K17*L17 -> 0
B18: Direct corp | C18: New Auto | D18: 4 | E18: 4 | F18: =E18/12 -> 0.33333333 | I18: 0.2
B19: Direct corp | C19: Used Auto | D19: 2 | E19: 2 | F19: =E19/12 -> 0.16666667 | I19: 0.2
B20: Total | D20: =SUM(D12:D19) -> 103 | E20: =SUM(E12:E19) -> 107 | F20: =SUM(F12:F19) -> 8.9166667 | H20: =SUM(H6:H19) -> 46.858447 | J20: =SUM(J8:J19) -> 231.1 | M20: =SUM(M12:M19) -> 0 | N20: =SUM(N12:N19) -> 0
B22: 2024 | C22: Customer view | D22: Customer view | E22: Dealer view | F22: Dealer view
B23: Product | C23: New Auto | D23: Used Auto | E23: New Auto | F23: Used Auto | G23: notes
B24: in €
B25: Auto loan | C25: 15000 | D25: 9500 | E25: =C25/(1+30%) -> 11538.462 | F25: =D25/(1+30%) -> 7307.6923 | G25: Considering 30%% markup
B26: Floor plan | C26: 0 | D26: 5000 | E26: =C26/(1+30%) -> 0 | F26: =D26/(1+30%) -> 3846.1538 | G26: Considering 30%% markup
B27: Stock finance
B28: Leasing | C28: 25000 | D28: 13000 | E28: =C28/(1+30%) -> 19230.769 | F28: =D28/(1+30%) -> 10000 | G28: Considering 30%% markup
B29: Other | E29: =C29/(1+30%) -> 0 | F29: =D29/(1+30%) -> 0 | G29: Considering 30%% markup
B31: 2. Product mix, %
C32: 2024
B33: Product | C33: Car type | D33: Segment | G33: Notes
B34: in % | D34: LeaseCos | E34: RAC | F34: Independent dealers | G34: Dealers with OEMs captives
A35: =B35&C35 -> Floor planNew Auto | B35: Floor plan | C35: New Auto | D35: 0 | E35: 0 | F35: 0.4 | G35: 0.7 | H35: Only Toyota, Mercedez and small syngelidis group brands have floor plan (only 1 brand)
A36: =B36&C36 -> Floor planUsed Auto | B36: Floor plan | C36: Used Auto | D36: 0 | E36: 0 | F36: 0 | G36: 0.4
A37: =B37&C37 -> Stock financeNew Auto | B37: Stock finance | C37: New Auto | D37: 0 | E37: 0 | F37: 0.15 | G37: 0.05
A38: =B38&C38 -> Stock financeUsed Auto | B38: Stock finance | C38: Used Auto | D38: 0 | E38: 0 | F38: 0.25 | G38: 0.05
A39: =B39&C39 -> LoanNew Auto | B39: Loan | C39: New Auto | D39: 0.3 | E39: 0.25 | F39: 0.15 | G39: 0.05
A40: =B40&C40 -> LoanUsed Auto | B40: Loan | C40: Used Auto | D40: 0 | E40: 0.4 | F40: 0.4 | G40: 0.3
A41: =B41&C41 -> Financial leaseNew Auto | B41: Financial lease | C41: New Auto | D41: 0.6 | E41: 0.5 | F41: 0.15 | G41: 0
A42: =B42&C42 -> Financial leaseUsed Auto | B42: Financial lease | C42: Used Auto | D42: 0 | E42: 0.2 | F42: 0 | G42: 0
A43: =B43&C43 -> Operational leaseNew Auto | B43: Operational lease | C43: New Auto | D43: 0 | E43: 0 | F43: 0 | G43: 0
...

Sheet B2B financing opportunity
B2: B2B Financing Opportunities: Target Wholesalers for Eurobank by 2030
B4: Product | C4: Importer | D4: Number of dealers | E4: Yearly number of cars sold | F4: Total line value | G4: Yearly cars financed | H4: Avg. Car value | I4: RAR per car | J4: Annual RAR | K4: Assumption for selecting the importer | L4: Notes
B5: Unit of measure | D5: # | E5: # | F5: €M | G5: # | H5: € | I5: € | J5: €
B6: Floor plan | C6: Toyota | D6: 20 | F6: 15
B7: Floor plan
B8: Floor plan
B9: Floor plan
B10: Floor plan
B11: Floor plan
B12: Floor plan
B13: Floor plan
B14: Floor plan
B15: Floor plan
B16: Floor plan
B17: Floor plan
B18: Floor plan
... B20: Floor plan
B23: Product | C23: Dealer Group | D23: Number of dealers | E23: Yearly number of cars sold | F23: Total line value | G23: Yearly cars financed | H23: Avg. Car value | I23: RAR per car | J23: Annual RAR | K23: Assumption for selecting the dealer | L23: Notes
B24: Unit of measure | D24: # | E24: # | F24: €M | G24: # | H24: € | I24: € | J24: €
B25: Stock finance
B26: Stock finance
B27: Stock finance
B28: Stock finance
B29: Stock finance
B30: Stock finance
B31: Stock finance
B32: Stock finance
B33: Stock finance
B34: Stock finance
B35: Stock finance
B36: Stock finance
... B39: Stock finance
B43: Product | C43: Fleet Group | D43: Number of dealers | E43: Yearly number of cars sold | F43: Total line value | G43: Yearly cars financed | H43: Avg. Car value | I43: RAR per car | J43: Annual RAR | K43: Assumption for selecting the dealer | L43: Notes
B44: Unit of measure | D44: # | E44: # | F44: €M | G44: # | H44: € | I44: € | J44: €
B45: Fleet financing
B46: Fleet financing
B47: Fleet financing
B48: Fleet financing
B49: Fleet financing
B50: Fleet financing
...
