Workbook

Sheet 2030 Market sizing exercise
B2: 2030 market sizing exercize

Sheet # of cars analysis
A1: # of cars in k | B1: Car Type | C1: 2024 | D1: 2030 | E1: growth (%)
B2: New Cars | C2: 137 | D2: 165 | E2: =+D2/C2-1 -> 0.20437956
B3: Used Cars | C3: 150 | D3: 200 | E3: =+D3/C3-1 -> 0.33333333
B4: Total | C4: =+C3+C2 -> 287 | D4: =+D3+D2 -> 365 | E4: =+D4/C4-1 -> 0.271777
B6: Breakdown per Segment and Car Type (2024)
B7: Segment | C7: New Cars | D7: Used Cars | E7: Total | F7: weight new cars (%) | G7: weight used cars (%) | H7: weight total (%)
B8: Retail | C8: 62 | D8: 135 | E8: =+D8+C8 -> 197 | F8: =+C8/C10 -> 0.45255474 | G8: =+D8/D10 -> 0.9 | H8: =+E8/E10 -> 0.68641115
B9: SME & Corp. | C9: 75 | D9: 15 | E9: =+D9+C9 -> 90 | F9: =+C9/C10 -> 0.54744526 | G9: =+D9/D10 -> 0.1 | H9: =+E9/E10 -> 0.31358885
B10: Total | C10: =+C9+C8 -> 137 | D10: =+D9+D8 -> 150 | E10: =+E9+E8 -> 287
B12: Breakdown per Segment and Car Type (2030)
B13: Segment | C13: New Cars | D13: Used Cars | E13: Total | F13: =+F7 -> weight new cars (%) | G13: =+G7 -> weight used cars (%) | H13: =+H7 -> weight total (%)
B14: Retail | C14: 75 | D14: 170 | E14: =+D14+C14 -> 245 | F14: =+C14/C16 -> 0.45454545 | G14: =+D14/D16 -> 0.85 | H14: =+E14/E16 -> 0.67123288
B15: SME & Corp. | C15: 90 | D15: 30 | E15: =+D15+C15 -> 120 | F15: =+C15/C16 -> 0.54545455 | G15: =+D15/D16 -> 0.15 | H15: =+E15/E16 -> 0.32876712
B16: Total | C16: 165 | D16: 200 | E16: =+D16+C16 -> 365
B18: % fin. Penetration per car type (2030)
B19: =+B1 -> Car Type | C19: Segment | D19: % fin. Penetration
B20: New Cars | C20: Retail | D20: 0.6
B21: Used Cars | C21: Retail | D21: 0.35
B22: New Cars | C22: SME/Corp | D22: 95% (Leasing)
B23: Used Cars | C23: SME/Corp | D23: 0.2
I24: 2030
B25: Total financed cars 2030 | I25: including cash car loans
B26: Segment | C26: Car Type | D26: # Sold 2030 | E26: % Financed | F26: # Financed | G26: Avg. Financed Amount | I26: ERB # car financed | J26: ERB MS (# cars)
B27: Retail | C27: New | D27: =+C14 -> 75 | E27: 0.6 | F27: =+E27*D27 -> 45 | G27: =+F27*15 -> 675 | I27: =+Summary!O10+Summary!O12 -> 15.349917 | J27: =+I27/F27 -> 0.34110927
B28: Retail | C28: Used | D28: =+D14 -> 170 | E28: 0.35 | F28: =+E28*D28 -> 59.5 | G28: =+F28*9.5 -> 565.25 | I28: =+Summary!O11+Summary!O13 -> 19.358669 | J28: =+I28/F28 -> 0.32535579
B29: SME & Corp. | C29: New | D29: =+C15 -> 90 | E29: 0.95 | F29: =+E29*D29 -> 85.5 | G29: =+F29*25 -> 2137.5 | I29: 2030
B30: SME & Corp. | C30: Used | D30: =+D15 -> 30 | E30: 0.2 | F30: =+E30*D30 -> 6 | G30: =+F30*13 -> 78 | I30: only car loans
B31: Σύνολο | C31: New & Used | D31: =SUM(D27:D30) -> 365 | E31: =+F31/D31 -> 0.5369863 | F31: =SUM(F27:F30) -> 196 | G31: =SUM(G27:G30) -> 3455.75 | I31: ERB # car financed | J31: ERB MS (# cars)
I32: =+Summary!O10 -> 13.937309 | J32: =+I32/F27 -> 0.30971799
B33: Car loans: 15k for new and 9,5 for used // Car Leases: 25k for new and 13 for used | I33: =+Summary!O11 -> 10.633893 | J33: =+I33/F28 -> 0.17872089
I34: 2030
B35: Total financed cars 2024 | I35: only car loans
B36: Segment | C36: Car Type | D36: # Sold 2030 | E36: % Financed | F36: # Financed | G36: Avg. Financed Amount | I36: ERB disb. Amount | J36: ERB MS | K36: avg. dis. Amount
B37: Retail | C37: New | D37: =+C8 -> 62 | E37: 0.5 | F37: =+E37*D37 -> 31 | G37: =+F37*15 -> 465 | I37: =+I32*Summary!O19 -> 218.04372 | J37: =+I37/G27 -> 0.32302773 | K37: =+I37/I32 -> 15.644606
B38: Retail | C38: Used | D38: =+D8 -> 135 | E38: 0.2 | F38: =+E38*D38 -> 27 | G38: =+F38*8.5 -> 229.5 | I38: =+I33*Summary!O20 -> 116.28029 | J38: =+I38/G28 -> 0.2057148 | K38: =+I38/I33 -> 10.934875
E45: ONLY CAR LOANS - 2030
G46: MARKET
E47: Segment | F47: Car Type | G47: Financed Amount
E48: Retail | F48: New | G48: =+G27 -> 675
E49: Retail | F49: Used | G49: =+G28 -> 565.25
...

Sheet 2030 RAR per Car
B2: Key figures for RAR and loan disbursements calculation
B4: Average loan amount | C4: 2024 | I4: 2030
B5: Product | C5: New | D5: Used | I5: Product | J5: New | K5: Used
B6: in € | I6: in €
B7: Auto loan | C7: 15000 | D7: 9500 | I7: Auto loan | J7: 17395.401 | K7: 11017.087
B8: Cash loan | C8: 5000 | D8: 5000 | I8: Cash loan | J8: 5798.4671 | K8: 5798.4671
B9: Financial lease | C9: 25000 | D9: 13000 | I9: Financial lease | J9: 28992.335 | K9: 15076.014
B10: Operational lease | C10: 25000 | D10: 13000 | I10: Operational lease | J10: 28992.335 | K10: 15076.014
B13: Eurobank RAR per car | C13: 2024 | I13: RAR per car | J13: 2030
B14: Product | C14: Car type | I14: Product | J14: Car type
B15: in € | C15: New | D15: Used | I15: in € | J15: New | K15: Used
B16: Auto loan | C16: 981.66667 | D16: 1363.7778 | I16: Auto loan | J16: 1138.4324 | K16: 1581.5641
B17: Cash loan | C17: 717.77778 | D17: 717.77778 | I17: Cash loan | J17: 832.40216 | K17: 832.40216
B18: Financial lease | C18: 1750 | D18: 962.5 | I18: Financial lease | J18: 2029.4635 | K18: 1116.2049
B19: Operational lease | C19: 3500 | D19: 1925 | I19: Operational lease | J19: 4058.927 | K19: 2232.4098 | N19: 8500
N20: =+Summary!O20*1000 -> 10934.875
N21: =+N20/N19-1 -> 0.28645586

Sheet Summary
B3: Retail | F3: Baseline | H3: Incremental 2024-30 | O3: Total 2030
C4: UoM | D4: Product | E4: Car type | F4: 2024 | G4: 2024-2030 organic growth in auto retail | H4: 1. Increase used car financing | I4: 2. Redesign end-to-end B2B offering | K4: 4. Expand digital presence | M4: Total incremental | O4: Total 2030
I5: Min. | J5: Max | K5: Min. | L5: Max | M5: Min | N5: Max | O5: Min | P5: Max
B6: RAR | C6: €M | D6: Auto loan | E6: New | F6: 10 | G6: =35%*(35)-F6 -> 2.25 | I6: 1.5 | J6: 2 | K6: ='4. Expand digital presence'!L6 -> 0.51975 | L6: ='4. Expand digital presence'!M6 -> 0.779625 | M6: =H6+I6+K6 -> 2.01975 | N6: =H6+J6+L6 -> 2.779625 | O6: =M6+$G6+$F6 -> 14.26975 | P6: =N6+$G6+$F6 -> 15.029625
B7: RAR | C7: €M | D7: Auto loan | E7: Used | F7: 4.3 | H7: ='1. Increase used car financing'!H28 -> 8 | I7: 1.5 | J7: 2 | K7: ='4. Expand digital presence'!L7 -> 2.3315022 | L7: ='4. Expand digital presence'!M7 -> 3.1457945 | M7: =H7+I7+K7 -> 11.831502 | N7: =H7+J7+L7 -> 13.145795 | O7: =M7+$G7+$F7 -> 16.131502 | P7: =N7+$G7+$F7 -> 17.445795
B8: RAR | C8: €M | D8: Cash loan | E8: New | F8: ='4. Expand digital presence'!J9 -> 0.78812 | G8: ='4. Expand digital presence'!K9-F8 -> 0.11188 | K8: ='4. Expand digital presence'!L9-'4. Expand digital presence'!K9 -> 0.15 | L8: ='4. Expand digital presence'!M9-'4. Expand digital presence'!K9 -> 0.3 | M8: =H8+I8+K8 -> 0.15 | N8: =H8+J8+L8 -> 0.3 | O8: =M8+$G8+$F8 -> 1.05 | P8: =N8+$G8+$F8 -> 1.2
B9: RAR | C9: €M | D9: Cash loan | E9: Used | F9: ='4. Expand digital presence'!J10 -> 4.4660133 | G9: ='4. Expand digital presence'!K10-F9 -> 0.63398667 | K9: ='4. Expand digital presence'!L10-'4. Expand digital presence'!K10 -> 1.4493296 | L9: ='4. Expand digital presence'!M10-'4. Expand digital presence'!K10 -> 2.3992178 | M9: =H9+I9+K9 -> 1.4493296 | N9: =H9+J9+L9 -> 2.3992178 | O9: =M9+$G9+$F9 -> 6.5493296 | P9: =N9+$G9+$F9 -> 7.4992178
B10: Cars financed | C10: k# | D10: Auto loan | E10: New | F10: =F6/INDEX('2030 RAR per Car'!$B$15:$G$19,MATCH($D10,'2030 RAR per Car'!$B$15:$B$19,0),MATCH($E10,'2030 RAR per Car'!$B$15:$G$15,0))*1000 -> 10.186757 | G10: =G6/INDEX('2030 RAR per Car'!$I$15:$K$19,MATCH($D10,'2030 RAR per Car'!$I$15:$I$19,0),MATCH($E10,'2030 RAR per Car'!$I$15:$K$15,0))*1000 -> 1.976402 | I10: =I6/INDEX('2030 RAR per Car'!$I$15:$K$19,MATCH($D10,'2030 RAR per Car'!$I$15:$I$19,0),MATCH($E10,'2030 RAR per Car'!$I$15:$K$15,0))*1000 -> 1.3176013 | J10: =J6/INDEX('2030 RAR per Car'!$I$15:$K$19,MATCH($D10,'2030 RAR per Car'!$I$15:$I$19,0),MATCH($E10,'2030 RAR per Car'!$I$15:$K$15,0))*1000 -> 1.7568018 | K10: ='4. Expand digital presence'!L14-'4. Expand digital presence'!$K14 -> 0.45654886 | L10: ='4. Expand digital presence'!M14-'4. Expand digital presence'!$K14 -> 0.68482329 | M10: =H10+I10+K10 -> 1.7741502 | N10: =H10+J10+L10 -> 2.4416251 | O10: =M10+$G10+$F10 -> 13.937309 | P10: =N10+$G10+$F10 -> 14.604784
B11: Cars financed | C11: k# | D11: Auto loan | E11: Used | F11: =F7/INDEX('2030 RAR per Car'!$B$15:$G$19,MATCH($D11,'2030 RAR per Car'!$B$15:$B$19,0),MATCH($E11,'2030 RAR per Car'!$B$15:$G$15,0))*1000 -> 3.1530064 | G11: =G7/INDEX('2030 RAR per Car'!$I$15:$K$19,MATCH($D11,'2030 RAR per Car'!$I$15:$I$19,0),MATCH($E11,'2030 RAR per Car'!$I$15:$K$15,0))*1000 -> 0 | H11: =H7/INDEX('2030 RAR per Car'!$I$15:$K$19,MATCH($D11,'2030 RAR per Car'!$I$15:$I$19,0),MATCH($E11,'2030 RAR per Car'!$I$15:$K$15,0))*1000 -> 5.0582837 | I11: =I7/INDEX('2030 RAR per Car'!$I$15:$K$19,MATCH($D11,'2030 RAR per Car'!$I$15:$I$19,0),MATCH($E11,'2030 RAR per Car'!$I$15:$K$15,0))*1000 -> 0.9484282 | J11: =J7/INDEX('2030 RAR per Car'!$I$15:$K$19,MATCH($D11,'2030 RAR per Car'!$I$15:$I$19,0),MATCH($E11,'2030 RAR per Car'!$I$15:$K$15,0))*1000 -> 1.2645709 | K11: ='4. Expand digital presence'!L15-'4. Expand digital presence'!$K15 -> 1.4741749 | L11: ='4. Expand digital presence'!M15-'4. Expand digital presence'!$K15 -> 1.9890402 | M11: =H11+I11+K11 -> 7.4808868 | N11: =H11+J11+L11 -> 8.3118948 | O11: =M11+$G11+$F11 -> 10.633893 | P11: =N11+$G11+$F11 -> 11.464901
B12: Cars financed | C12: k# | D12: Cash loan | E12: New | F12: =F8/INDEX('2030 RAR per Car'!$B$15:$G$19,MATCH($D12,'2030 RAR per Car'!$B$15:$B$19,0),MATCH($E12,'2030 RAR per Car'!$B$15:$G$15,0))*1000 -> 1.098 | G12: =G8/INDEX('2030 RAR per Car'!$I$15:$K$19,MATCH($D12,'2030 RAR per Car'!$I$15:$I$19,0),MATCH($E12,'2030 RAR per Car'!$I$15:$K$15,0))*1000 -> 0.13440619 | K12: ='4. Expand digital presence'!L17-'4. Expand digital presence'!$K17 -> 0.18020136 | L12: ='4. Expand digital presence'!M17-'4. Expand digital presence'!$K17 -> 0.36040271 | M12: =H12+I12+K12 -> 0.18020136 | N12: =H12+J12+L12 -> 0.36040271 | O12: =M12+$G12+$F12 -> 1.4126075 | P12: =N12+$G12+$F12 -> 1.5928089
B13: Cars financed | C13: k# | D13: Cash loan | E13: Used | F13: =F9/INDEX('2030 RAR per Car'!$B$15:$G$19,MATCH($D13,'2030 RAR per Car'!$B$15:$B$19,0),MATCH($E13,'2030 RAR per Car'!$B$15:$G$15,0))*1000 -> 6.222 | G13: =G9/INDEX('2030 RAR per Car'!$I$15:$K$19,MATCH($D13,'2030 RAR per Car'!$I$15:$I$19,0),MATCH($E13,'2030 RAR per Car'!$I$15:$K$15,0))*1000 -> 0.76163505 | K13: ='4. Expand digital presence'!L18-'4. Expand digital presence'!$K18 -> 1.741141 | L13: ='4. Expand digital presence'!M18-'4. Expand digital presence'!$K18 -> 2.8822821 | M13: =H13+I13+K13 -> 1.741141 | N13: =H13+J13+L13 -> 2.8822821 | O13: =M13+$G13+$F13 -> 8.7247761 | P13: =N13+$G13+$F13 -> 9.8659171
B14: Loan disbursements | C14: €M | D14: Auto loan | E14: New | F14: =F10*INDEX('2030 RAR per Car'!$B$5:$D$10,MATCH($D14,'2030 RAR per Car'!$B$5:$B$10,0),MATCH($E14,'2030 RAR per Car'!$B$5:$D$5,0))/1000 -> 152.80136 | G14: =G10*INDEX('2030 RAR per Car'!$I$5:$K$10,MATCH($D14,'2030 RAR per Car'!$I$5:$I$10,0),MATCH($E14,'2030 RAR per Car'!$I$5:$K$5,0))/1000 -> 34.380306 | I14: =I10*INDEX('2030 RAR per Car'!$I$5:$K$10,MATCH($D14,'2030 RAR per Car'!$I$5:$I$10,0),MATCH($E14,'2030 RAR per Car'!$I$5:$K$5,0))/1000 -> 22.920204 | J14: =J10*INDEX('2030 RAR per Car'!$I$5:$K$10,MATCH($D14,'2030 RAR per Car'!$I$5:$I$10,0),MATCH($E14,'2030 RAR per Car'!$I$5:$K$5,0))/1000 -> 30.560272 | K14: ='4. Expand digital presence'!L20-'4. Expand digital presence'!$K20 -> 7.9418506 | L14: ='4. Expand digital presence'!M20-'4. Expand digital presence'!$K20 -> 11.912776 | M14: =H14+I14+K14 -> 30.862054 | N14: =H14+J14+L14 -> 42.473048 | O14: =M14+$G14+$F14 -> 218.04372 | P14: =N14+$G14+$F14 -> 229.65471
B15: Loan disbursements | C15: €M | D15: Auto loan | E15: Used | F15: =F11*INDEX('2030 RAR per Car'!$B$5:$D$10,MATCH($D15,'2030 RAR per Car'!$B$5:$B$10,0),MATCH($E15,'2030 RAR per Car'!$B$5:$D$5,0))/1000 -> 29.95356 | H15: ='1. Increase used car financing'!H33 -> 59.6367 | I15: =I11*INDEX('2030 RAR per Car'!$I$5:$K$10,MATCH($D15,'2030 RAR per Car'!$I$5:$I$10,0),MATCH($E15,'2030 RAR per Car'!$I$5:$K$5,0))/1000 -> 10.448916 | J15: =J11*INDEX('2030 RAR per Car'!$I$5:$K$10,MATCH($D15,'2030 RAR per Car'!$I$5:$I$10,0),MATCH($E15,'2030 RAR per Car'!$I$5:$K$5,0))/1000 -> 13.931889 | K15: ='4. Expand digital presence'!L21-'4. Expand digital presence'!$K21 -> 16.241114 | L15: ='4. Expand digital presence'!M21-'4. Expand digital presence'!$K21 -> 21.137597 | M15: =H15+I15+K15 -> 86.32673 | N15: =H15+J15+L15 -> 94.706186 | O15: =M15+$G15+$F15 -> 116.28029 | P15: =N15+$G15+$F15 -> 124.65975
B16: Loan disbursements | C16: €M | D16: Cash loan | E16: New | F16: =F12*INDEX('2030 RAR per Car'!$B$5:$D$10,MATCH($D16,'2030 RAR per Car'!$B$5:$B$10,0),MATCH($E16,'2030 RAR per Car'!$B$5:$D$5,0))/1000 -> 5.49 | G16: =G12*INDEX('2030 RAR per Car'!$I$5:$K$10,MATCH($D16,'2030 RAR per Car'!$I$5:$I$10,0),MATCH($E16,'2030 RAR per Car'!$I$5:$K$5,0))/1000 -> 0.77934985 | K16: ='4. Expand digital presence'!L24-'4. Expand digital presence'!$K24 -> 1.0448916 | L16: ='4. Expand digital presence'!M24-'4. Expand digital presence'!$K24 -> 2.0897833 | M16: =H16+I16+K16 -> 1.0448916 | N16: =H16+J16+L16 -> 2.0897833 | O16: =M16+$G16+$F16 -> 7.3142415 | P16: =N16+$G16+$F16 -> 8.3591331
B17: Loan disbursements | C17: €M | D17: Cash loan | E17: Used | F17: =F13*INDEX('2030 RAR per Car'!$B$5:$D$10,MATCH($D17,'2030 RAR per Car'!$B$5:$B$10,0),MATCH($E17,'2030 RAR per Car'!$B$5:$D$5,0))/1000 -> 31.11 | G17: =G13*INDEX('2030 RAR per Car'!$I$5:$K$10,MATCH($D17,'2030 RAR per Car'!$I$5:$I$10,0),MATCH($E17,'2030 RAR per Car'!$I$5:$K$5,0))/1000 -> 4.4163158 | K17: ='4. Expand digital presence'!L25-'4. Expand digital presence'!$K25 -> 10.095949 | L17: ='4. Expand digital presence'!M25-'4. Expand digital presence'!$K25 -> 16.712818 | M17: =H17+I17+K17 -> 10.095949 | N17: =H17+J17+L17 -> 16.712818 | O17: =M17+$G17+$F17 -> 45.622265 | P17: =N17+$G17+$F17 -> 52.239133
I19: =+I14/I10 -> 17.395401 | K19: =+K14/K10 -> 17.395401 | M19: =+M14/M10 -> 17.395401 | O19: =+O14/O10 -> 15.644606
H20: =+H15/H11 -> 11.789908 | I20: =+I15/I11 -> 11.017087 | K20: =+K15/K11 -> 11.017087 | M20: =+M15/M11 -> 11.539639 | O20: =+O15/O11 -> 10.934875
K21: =+K16/K12 -> 5.7984671 | M21: =+M16/M12 -> 5.7984671 | O21: =+O16/O12 -> 5.1778298
K22: =+K17/K13 -> 5.7984671 | M22: =+M17/M13 -> 5.7984671 | O22: =+O17/O13 -> 5.2290471
D26: M€ | F26: USED CARS | G26: B2B KICK BACK | H26: DIGITAL EXPAND | I26: TOTAL
D27: =+B8 -> RAR
D28: Auto loan | E28: New | F28: =+H6 -> 0 | G28: =+J6 -> 2 | H28: =+L6 -> 0.779625 | I28: =SUM(F28:H28) -> 2.779625
D29: Auto loan | E29: Used | F29: =+H7 -> 8 | G29: =+J7 -> 2 | H29: =+L7 -> 3.1457945 | I29: =SUM(F29:H29) -> 13.145795
D30: Cash loan | E30: New | F30: =+H8 -> 0 | G30: =+J8 -> 0 | H30: =+L8 -> 0.3 | I30: =SUM(F30:H30) -> 0.3
D31: Cash loan | E31: Used | F31: =+H9 -> 0 | G31: =+J9 -> 0 | H31: =+L9 -> 2.3992178 | I31: =SUM(F31:H31) -> 2.3992178
D32: Disbursements
D33: Auto loan | E33: New | F33: =+H14 -> 0 | G33: =+J14 -> 30.560272 | H33: =+L14 -> 11.912776 | I33: =SUM(F33:H33) -> 42.473048 | J33: =+F33/$I$33 -> 0 | K33: =+G33/$I$33 -> 0.71952152 | L33: =+H33/$I$33 -> 0.28047848
D34: Auto loan | E34: Used | F34: =+H15 -> 59.6367 | G34: =+J15 -> 13.931889 | H34: =+L15 -> 21.137597 | I34: =SUM(F34:H34) -> 94.706186 | J34: =+F34/$I$34 -> 0.62970227 | K34: =+G34/$I$34 -> 0.14710643 | L34: =+H34/$I$34 -> 0.22319131
D35: Cash loan | E35: New | F35: =+H16 -> 0 | G35: =+J16 -> 0 | H35: =+L16 -> 2.0897833 | I35: =SUM(F35:H35) -> 2.0897833 | J35: =+F35/$I$35 -> 0 | K35: =+G35/$I$35 -> 0 | L35: =+H35/$I$35 -> 1
D36: Cash loan | E36: Used | F36: =+H17 -> 0 | G36: =+J17 -> 0 | H36: =+L17 -> 16.712818 | I36: =SUM(F36:H36) -> 16.712818 | J36: =+F36/$I$36 -> 0 | K36: =+G36/$I$36 -> 0 | L36: =+H36/$I$36 -> 1

Sheet Sheet3
B3: New | E3: Market growth new cars | J3: 35
J4: 0.35
E5: RAR | J5: =J4*J3 -> 12.25
E6: Cars financed | J6: =(J5*1000)/'2030 RAR per Car'!J16 -> 10.760411
B7: B2B opportunity | E7: RAR | F7: €M | J7: =3*50% -> 1.5 | K7: =50%*4 -> 2 | M7: 50% new and 50 % used | T7: 3 | U7: 4
C8: New | E8: Cars financed | F8: €M | J8: =J7*1000/'2030 RAR per Car'!J16 -> 1.3176013 | K8: =K7*1000/'2030 RAR per Car'!J16 -> 1.7568018
C9: Used | E9: RAR | F9: €M | J9: =3*50% -> 1.5 | K9: =50%*4 -> 2
C10: Used | E10: Cars financed | F10: €M | J10: =J9*1000/'2030 RAR per Car'!K16 -> 0.9484282 | K10: =K9*1000/'2030 RAR per Car'!K16 -> 1.2645709
B12: D2C | C12: Total | D12: Cash loan | E12: RAR | F12: €M | J12: 2 | K12: 3
C13: New | D13: Cash loan | E13: RAR | F13: €M | J13: =15%*J12 -> 0.3 | K13: =15%*K12 -> 0.45
B14: D2C | C14: New | D14: Cash loan | E14: cars financed | F14: k# | J14: =J13*1000/'2030 RAR per Car'!J16 -> 0.26352026 | K14: =K13*1000/'2030 RAR per Car'!J16 -> 0.3952804 | M14: B2C cars
M15: B2C is new
B16: Toyota | C16: Total | D16: Auto loan | E16: RAR | F16: €M | J16: 1 | K16: 2
C17: New | D17: Auto loan | E17: RAR | F17: €M | J17: =70%*J16 -> 0.7 | K17: =70%*K16 -> 1.4
C18: New | D18: Auto loan | E18: cars financed | F18: k# | J18: =J17*1000/'2030 RAR per Car'!J16 -> 0.61488062 | K18: =J17*1000/'2030 RAR per Car'!J16 -> 0.61488062
C19: Used | D19: Auto loan | E19: RAR | F19: €M | J19: =J16-J17 -> 0.3 | K19: =K16-K17 -> 0.6
C20: Used | D20: Auto loan | E20: cars financed | F20: k# | J20: =J19*1000/'2030 RAR per Car'!K16 -> 0.18968564 | K20: =K19*1000/'2030 RAR per Car'!K16 -> 0.37937128
B22: Used car finacing | E22: cars financed | F22: k# | J22: ='1. Increase used car financing'!H30 -> 8 | K22: =J22 -> 8
B24: Digital presence (Car.gr + Cardom) | E24: RAR | F24: €M | J24: ='4. Expand digital presence'!L82+'4. Expand digital presence'!L84 -> 2.1087522 | K24: ='4. Expand digital presence'!M82+'4. Expand digital presence'!M84 -> 2.8116695
E25: cars financed | F25: k# | J25: =J24*1000/'2030 RAR per Car'!K16 -> 1.3333333 | K25: =K24*1000/'2030 RAR per Car'!K16 -> 1.7777778
B27: Total | C27: New | J27: =J6+J8+J17 -> 12.778012 | K27: =J6+K8+K17 -> 13.917213 | M27: C2C is used
C28: Used | J28: =J25+J22+J20+J10 -> 10.471447 | K28: =K25+K22+K20+K10 -> 11.42172

Sheet 1. Increase used car financing
B3: Increase used car financing
B5: Used car market
B6: Item | C6: UoM | D6: 2021 | E6: =D6+1 -> 2022 | F6: =E6+1 -> 2023 | G6: =F6+1 -> 2024 | I6: Notes
B7: Used car market | C7: # | D7: 130000 | E7: 140000 | F7: 140000 | G7: 150000
B8: O/w individuals' used car sales | C8: # | D8: =90%*D7 -> 117000 | E8: =90%*E7 -> 126000 | F8: =90%*F7 -> 126000 | G8: =90%*G7 -> 135000
B9: Share of cars sold via dealers' (B2C) | C9: % | D9: 0.45 | E9: 0.45 | F9: 0.45 | G9: 0.45
B10: Cars sold via dealers' channels (B2C) | C10: # | D10: =D9*D7 -> 58500 | E10: =E9*E7 -> 63000 | F10: =F9*F7 -> 63000 | G10: =G9*G7 -> 67500
B11: Financed via dealers' channels | C11: # | D11: =35%*D10 -> 20475 | E11: =35%*E10 -> 22050 | F11: =35%*F10 -> 22050 | G11: =35%*G10 -> 23625 | I11: assuming 35% financing penetration
B12: Non financed | C12: # | D12: =D10-D11 -> 38025 | E12: =E10-E11 -> 40950 | F12: =F10-F11 -> 40950 | G12: =G10-G11 -> 43875
B13: ERB used car applications disbursed | C13: # | D13: 4657 | E13: 4081 | F13: 3643 | G13: 3291
B14: ERB used car applications approved | C14: # | D14: 786 | E14: 627 | F14: 543 | G14: 467
B15: ERB used car Counteroffer & Cancelled | C15: # | D15: 2389 | E15: 1952 | F15: 2229 | G15: 2188
B16: ERB used car applications rejected | C16: # | D16: 2375 | E16: 2667 | F16: 2886 | G16: 2952
B17: ERB booking rate | C17: % | D17: =D13/SUM(D13:D16) -> 0.45625551 | E17: =E13/SUM(E13:E16) -> 0.43754691 | F17: =F13/SUM(F13:F16) -> 0.39167831 | G17: =G13/SUM(G13:G16) -> 0.3698584
B18: ERB used auto loan applications/ financed cars via dealer channel | C18: % | D18: =SUM(D13:D16)/D11 -> 0.49851038 | E18: =SUM(E13:E16)/E11 -> 0.4229932 | F18: =SUM(F13:F16)/F11 -> 0.42181406 | G18: =SUM(G13:G16)/G11 -> 0.37663492
B21: ERB 2030 ambition in used car market
G22: 2024 | H22: 2030 | I22: Notes
B23: Used car market through dealers’ channels RAR, incl. captive banks | C23: €M | G23: 27 | H23: 45 | I23: market sizing exercise
B24: ERB MS, incl. captive banks | C24: % | G24: 0.13 | H24: 0.26 | I24: market sizing exercise
B25: Used car market through dealers’ channels RAR, excl. captive banks | C25: €M | G25: 24 | H25: 40 | I25: market sizing exercise
B26: ERB MS, excl. captive banks | C26: % | G26: 0.15 | H26: 0.3 | I26: market sizing exercise
B27: ERB RAR | C27: €M | G27: =ROUND(G26*G25,0) -> 4 | H27: =ROUND(H26*H25,0) -> 12
B28: o/w incremental RAR 2024-2030 | C28: €M | H28: =H27-G27 -> 8
B29: RAR per used car | C29: k€ | G29: ='2030 RAR per Car'!D16/1000 -> 1.3637778 | H29: ='2030 RAR per Car'!K16/1000 -> 1.5815641 | I29: market sizing exercise
B30: ERB cars financed | C30: #k | G30: =ROUND(G27/G29,0) -> 3 | H30: =ROUND(H27/H29,0) -> 8
B31: Avg. loan amount | C31: k€ | G31: ='2030 RAR per Car'!D7/1000 -> 9.5 | H31: ='2030 RAR per Car'!K7/1000 -> 11.017087 | I31: market sizing exercise
B32: Loan disbursements | C32: €M | G32: =G30*G31 -> 28.5 | H32: =H30*H31 -> 88.1367
B33: o/w incremental 2024-2030 | C33: €M | H33: =H32-G32 -> 59.6367
B36: Summary of business cases
B37: Item | C37: UoM | G37: 2024 | H37: 2030 | I37: Notes
B38: Total RAR 2024-2030 (ERB ambition) | C38: €M | G38: =G27 -> 4 | H38: =H27 -> 12
B39: o/w incremental RAR 2024-2030 | H39: =H38-G38 -> 8 | I39: for Steering Commitee slide considered 7-9 €M range
B40: Total RAR 2024-2030 of business cases | G40: =G52+G67+G81 -> 4.0913333 | H40: =H52+I67-H67+I81-H81 -> 12.907821
B41: o/w incremental RAR 2024-2030 | C41: €M | H41: =H53+I68+I82 -> 8.8164872
B42: Loan disbursements | C42: €M | G42: =G55+G70+G84 -> 28.5 | H42: =H55+I70-H70+I84-H84 -> 89.238409
B43: o/w incremental 2024-2030 | C43: €M | H43: =H42-G42 -> 60.738409
H44: =+H43/('2030 RAR per Car'!D7/1000) -> 6.3935167
B46: Business case 1: Introducing consumer lending AA models
G47: 2024 | H47: 2030 | I47: Notes
B48: Booking rate | C48: % | G48: =G17 -> 0.3698584 | H48: 0.45 | I48: Based on preliminary testing of new AA models to Q1 2024 production (source: Credit policy team)
...

Sheet 4. Expand digital presence
C3: Summary of business cases
C4: Business case | D4: Segment | E4: Product | F4: Car type | G4: Channel | H4: Item | I4: UoM | J4: 2024 | K4: 2024-30 growth | L4: 2030 | O4: Notes/ source
L5: Min | M5: Max
A6: Summary | C6: Expand digital presence | D6: Retail | E6: Auto loan | F6: New | H6: RAR | I6: €M | J6: =SUMIFS(J$70:J$156,$H$70:$H$156,$H6,$F$70:$F$156,$F6,$E$70:$E$156,$E6,$A$70:$A$156,$A6) -> 0 | K6: =SUMIFS(K$70:K$156,$H$70:$H$156,$H6,$F$70:$F$156,$F6,$E$70:$E$156,$E6,$A$70:$A$156,$A6) -> 0 | L6: =SUMIFS(L$70:L$156,$H$70:$H$156,$H6,$F$70:$F$156,$F6,$E$70:$E$156,$E6,$A$70:$A$156,$A6) -> 0.51975 | M6: =SUMIFS(M$70:M$156,$H$70:$H$156,$H6,$F$70:$F$156,$F6,$E$70:$E$156,$E6,$A$70:$A$156,$A6) -> 0.779625
A7: Summary | C7: Expand digital presence | D7: Retail | E7: Auto loan | F7: Used | H7: RAR | I7: €M | J7: =SUMIFS(J$70:J$156,$H$70:$H$156,$H7,$F$70:$F$156,$F7,$E$70:$E$156,$E7,$A$70:$A$156,$A7) -> 0 | K7: =SUMIFS(K$70:K$156,$H$70:$H$156,$H7,$F$70:$F$156,$F7,$E$70:$E$156,$E7,$A$70:$A$156,$A7) -> 0 | L7: =SUMIFS(L$70:L$156,$H$70:$H$156,$H7,$F$70:$F$156,$F7,$E$70:$E$156,$E7,$A$70:$A$156,$A7) -> 2.3315022 | M7: =SUMIFS(M$70:M$156,$H$70:$H$156,$H7,$F$70:$F$156,$F7,$E$70:$E$156,$E7,$A$70:$A$156,$A7) -> 3.1457945
A8: Summary | C8: Expand digital presence | D8: Retail | E8: Auto loan | F8: Total | H8: RAR | I8: €M | J8: =SUM(J6:J7) -> 0 | K8: =SUM(K6:K7) -> 0 | L8: =SUM(L6:L7) -> 2.8512522 | M8: =SUM(M6:M7) -> 3.9254195
A9: Summary | C9: Expand digital presence | D9: Retail | E9: Cash loan | F9: New | H9: RAR | I9: €M | J9: =SUMIFS(J$70:J$156,$H$70:$H$156,$H9,$F$70:$F$156,$F9,$E$70:$E$156,$E9,$A$70:$A$156,$A9) -> 0.78812 | K9: =SUMIFS(K$70:K$156,$H$70:$H$156,$H9,$F$70:$F$156,$F9,$E$70:$E$156,$E9,$A$70:$A$156,$A9) -> 0.9 | L9: =SUMIFS(L$70:L$156,$H$70:$H$156,$H9,$F$70:$F$156,$F9,$E$70:$E$156,$E9,$A$70:$A$156,$A9) -> 1.05 | M9: =SUMIFS(M$70:M$156,$H$70:$H$156,$H9,$F$70:$F$156,$F9,$E$70:$E$156,$E9,$A$70:$A$156,$A9) -> 1.2
A10: Summary | C10: Expand digital presence | D10: Retail | E10: Cash loan | F10: Used | H10: RAR | I10: €M | J10: =SUMIFS(J$70:J$156,$H$70:$H$156,$H10,$F$70:$F$156,$F10,$E$70:$E$156,$E10,$A$70:$A$156,$A10) -> 4.4660133 | K10: =SUMIFS(K$70:K$156,$H$70:$H$156,$H10,$F$70:$F$156,$F10,$E$70:$E$156,$E10,$A$70:$A$156,$A10) -> 5.1 | L10: =SUMIFS(L$70:L$156,$H$70:$H$156,$H10,$F$70:$F$156,$F10,$E$70:$E$156,$E10,$A$70:$A$156,$A10) -> 6.5493296 | M10: =SUMIFS(M$70:M$156,$H$70:$H$156,$H10,$F$70:$F$156,$F10,$E$70:$E$156,$E10,$A$70:$A$156,$A10) -> 7.4992178
A11: Summary | C11: Expand digital presence | D11: Retail | E11: Cash loan | F11: Total | H11: RAR | I11: €M | J11: =SUM(J9:J10) -> 5.2541333 | K11: =SUM(K9:K10) -> 6 | L11: =SUM(L9:L10) -> 7.5993296 | M11: =SUM(M9:M10) -> 8.6992178
A12: Summary | C12: Total | D12: Retail | E12: Loan | F12: Used | G12: Total | H12: RAR | I12: €M | J12: =J11+J8 -> 5.2541333 | K12: =K11+K8 -> 6 | L12: =L11+L8 -> 10.450582 | M12: =M11+M8 -> 12.624637
A13: Summary | C13: Eurobank | D13: Retail | E13: Personal cash loan | F13: Total | G13: Total | H13: o/w incremental RAR 2024-2030 | I13: €M | L13: =L12-K12 -> 4.4505817 | M13: =M12-K12 -> 6.6246374
A14: Summary | C14: Expand digital presence | D14: Retail | E14: Auto loan | F14: New | G14: Total | H14: cars financed | I14: k# | J14: =SUMIFS(J$70:J$156,$H$70:$H$156,$H14,$F$70:$F$156,$F14,$E$70:$E$156,$E14,$A$70:$A$156,$A14) -> 0 | K14: =SUMIFS(K$70:K$156,$H$70:$H$156,$H14,$F$70:$F$156,$F14,$E$70:$E$156,$E14,$A$70:$A$156,$A14) -> 0 | L14: =SUMIFS(L$70:L$156,$H$70:$H$156,$H14,$F$70:$F$156,$F14,$E$70:$E$156,$E14,$A$70:$A$156,$A14) -> 0.45654886 | M14: =SUMIFS(M$70:M$156,$H$70:$H$156,$H14,$F$70:$F$156,$F14,$E$70:$E$156,$E14,$A$70:$A$156,$A14) -> 0.68482329
A15: Summary | C15: Expand digital presence | D15: Retail | E15: Auto loan | F15: Used | G15: Total | H15: cars financed | I15: k# | J15: =SUMIFS(J$70:J$156,$H$70:$H$156,$H15,$F$70:$F$156,$F15,$E$70:$E$156,$E15,$A$70:$A$156,$A15) -> 0 | K15: =SUMIFS(K$70:K$156,$H$70:$H$156,$H15,$F$70:$F$156,$F15,$E$70:$E$156,$E15,$A$70:$A$156,$A15) -> 0 | L15: =SUMIFS(L$70:L$156,$H$70:$H$156,$H15,$F$70:$F$156,$F15,$E$70:$E$156,$E15,$A$70:$A$156,$A15) -> 1.4741749 | M15: =SUMIFS(M$70:M$156,$H$70:$H$156,$H15,$F$70:$F$156,$F15,$E$70:$E$156,$E15,$A$70:$A$156,$A15) -> 1.9890402
A16: Summary | C16: Expand digital presence | D16: Retail | E16: Auto loan | F16: Total | G16: Total | H16: cars financed | I16: k# | J16: =SUM(J14:J15) -> 0 | K16: =SUM(K14:K15) -> 0 | L16: =SUM(L14:L15) -> 1.9307238 | M16: =SUM(M14:M15) -> 2.6738634
A17: Summary | C17: Expand digital presence | D17: Retail | E17: Cash loan | F17: New | G17: Total | H17: cars financed | I17: k# | J17: =SUMIFS(J$70:J$156,$H$70:$H$156,$H17,$F$70:$F$156,$F17,$E$70:$E$156,$E17,$A$70:$A$156,$A17) -> 1.098 | K17: =SUMIFS(K$70:K$156,$H$70:$H$156,$H17,$F$70:$F$156,$F17,$E$70:$E$156,$E17,$A$70:$A$156,$A17) -> 1.0812081 | L17: =SUMIFS(L$70:L$156,$H$70:$H$156,$H17,$F$70:$F$156,$F17,$E$70:$E$156,$E17,$A$70:$A$156,$A17) -> 1.2614095 | M17: =SUMIFS(M$70:M$156,$H$70:$H$156,$H17,$F$70:$F$156,$F17,$E$70:$E$156,$E17,$A$70:$A$156,$A17) -> 1.4416109
A18: Summary | C18: Expand digital presence | D18: Retail | E18: Cash loan | F18: Used | G18: Total | H18: cars financed | I18: k# | J18: =SUMIFS(J$70:J$156,$H$70:$H$156,$H18,$F$70:$F$156,$F18,$E$70:$E$156,$E18,$A$70:$A$156,$A18) -> 6.222 | K18: =SUMIFS(K$70:K$156,$H$70:$H$156,$H18,$F$70:$F$156,$F18,$E$70:$E$156,$E18,$A$70:$A$156,$A18) -> 6.1268462 | L18: =SUMIFS(L$70:L$156,$H$70:$H$156,$H18,$F$70:$F$156,$F18,$E$70:$E$156,$E18,$A$70:$A$156,$A18) -> 7.8679872 | M18: =SUMIFS(M$70:M$156,$H$70:$H$156,$H18,$F$70:$F$156,$F18,$E$70:$E$156,$E18,$A$70:$A$156,$A18) -> 9.0091282
A19: Summary | C19: Expand digital presence | D19: Retail | E19: Cash loan | F19: Total | G19: Total | H19: cars financed | I19: k# | J19: =SUM(J17:J18) -> 7.32 | K19: =SUM(K17:K18) -> 7.2080543 | L19: =SUM(L17:L18) -> 9.1293967 | M19: =SUM(M17:M18) -> 10.450739
A20: Summary | C20: Expand digital presence | D20: Retail | E20: Auto loan | F20: New | G20: Total | H20: Loan disbursements | I20: €M | J20: =SUMIFS(J$70:J$156,$H$70:$H$156,$H20,$F$70:$F$156,$F20,$E$70:$E$156,$E20,$A$70:$A$156,$A20) -> 0 | K20: =SUMIFS(K$70:K$156,$H$70:$H$156,$H20,$F$70:$F$156,$F20,$E$70:$E$156,$E20,$A$70:$A$156,$A20) -> 0 | L20: =SUMIFS(L$70:L$156,$H$70:$H$156,$H20,$F$70:$F$156,$F20,$E$70:$E$156,$E20,$A$70:$A$156,$A20) -> 7.9418506 | M20: =SUMIFS(M$70:M$156,$H$70:$H$156,$H20,$F$70:$F$156,$F20,$E$70:$E$156,$E20,$A$70:$A$156,$A20) -> 11.912776
A21: Summary | C21: Expand digital presence | D21: Retail | E21: Auto loan | F21: Used | G21: Total | H21: Loan disbursements | I21: €M | J21: =SUMIFS(J$70:J$156,$H$70:$H$156,$H21,$F$70:$F$156,$F21,$E$70:$E$156,$E21,$A$70:$A$156,$A21) -> 0 | K21: =SUMIFS(K$70:K$156,$H$70:$H$156,$H21,$F$70:$F$156,$F21,$E$70:$E$156,$E21,$A$70:$A$156,$A21) -> 0 | L21: =SUMIFS(L$70:L$156,$H$70:$H$156,$H21,$F$70:$F$156,$F21,$E$70:$E$156,$E21,$A$70:$A$156,$A21) -> 16.241114 | M21: =SUMIFS(M$70:M$156,$H$70:$H$156,$H21,$F$70:$F$156,$F21,$E$70:$E$156,$E21,$A$70:$A$156,$A21) -> 21.137597
A22: Summary | C22: Expand digital presence | D22: Retail | E22: Auto loan | F22: Total | G22: Total | H22: Loan disbursements | I22: €M | J22: =SUM(J20:J21) -> 0 | K22: =SUM(K20:K21) -> 0 | L22: =SUM(L20:L21) -> 24.182965 | M22: =SUM(M20:M21) -> 33.050373
C23: Expand digital presence | D23: Retail | E23: Auto loan | F23: Total | G23: Total | H23: o/w incremental 2024-2030 | I23: €M | K23: =K22-J22 -> 0 | L23: =L22-K22 -> 24.182965 | M23: =M22-K22 -> 33.050373
A24: Summary | C24: Expand digital presence | D24: Retail | E24: Cash loan | F24: New | G24: Total | H24: Loan disbursements | I24: €M | J24: =SUMIFS(J$70:J$156,$H$70:$H$156,$H24,$F$70:$F$156,$F24,$E$70:$E$156,$E24,$A$70:$A$156,$A24) -> 5.49 | K24: =SUMIFS(K$70:K$156,$H$70:$H$156,$H24,$F$70:$F$156,$F24,$E$70:$E$156,$E24,$A$70:$A$156,$A24) -> 6.2693498 | L24: =SUMIFS(L$70:L$156,$H$70:$H$156,$H24,$F$70:$F$156,$F24,$E$70:$E$156,$E24,$A$70:$A$156,$A24) -> 7.3142415 | M24: =SUMIFS(M$70:M$156,$H$70:$H$156,$H24,$F$70:$F$156,$F24,$E$70:$E$156,$E24,$A$70:$A$156,$A24) -> 8.3591331
A25: Summary | C25: Expand digital presence | D25: Retail | E25: Cash loan | F25: Used | G25: Total | H25: Loan disbursements | I25: €M | J25: =SUMIFS(J$70:J$156,$H$70:$H$156,$H25,$F$70:$F$156,$F25,$E$70:$E$156,$E25,$A$70:$A$156,$A25) -> 31.11 | K25: =SUMIFS(K$70:K$156,$H$70:$H$156,$H25,$F$70:$F$156,$F25,$E$70:$E$156,$E25,$A$70:$A$156,$A25) -> 35.526316 | L25: =SUMIFS(L$70:L$156,$H$70:$H$156,$H25,$F$70:$F$156,$F25,$E$70:$E$156,$E25,$A$70:$A$156,$A25) -> 45.622265 | M25: =SUMIFS(M$70:M$156,$H$70:$H$156,$H25,$F$70:$F$156,$F25,$E$70:$E$156,$E25,$A$70:$A$156,$A25) -> 52.239133
A26: Summary | C26: Expand digital presence | D26: Retail | E26: Cash loan | F26: Total | G26: Total | H26: Loan disbursements | I26: €M | J26: =SUM(J24:J25) -> 36.6 | K26: =SUM(K24:K25) -> 41.795666 | L26: =SUM(L24:L25) -> 52.936506 | M26: =SUM(M24:M25) -> 60.598267
C27: Expand digital presence | D27: Retail | E27: Cash loan | F27: Total | G27: Total | H27: o/w incremental 2024-2030 | I27: €M | K27: =K26-J26 -> 5.1956656 | L27: =L26-K26 -> 11.140841 | M27: =M26-K26 -> 18.802601
C28: Expand digital presence | D28: Retail | E28: Total | F28: Total | G28: Total | H28: Loan disbursements | I28: €M | J28: =J22+J26 -> 36.6 | K28: =K22+K26 -> 41.795666 | L28: =L22+L26 -> 77.119471 | M28: =M22+M26 -> 93.64864
C29: Expand digital presence | D29: Retail | E29: Total | F29: Total | G29: Total | H29: o/w incremental 2024-2030 | I29: €M | K29: =K28-J28 -> 5.1956656 | L29: =L28-K28 -> 35.323805 | M29: =M28-K28 -> 51.852974
C31: 1. Digital marketplaces
K32: =+C89 -> Cardom | L32: =+L89*1000 -> 133.33333
K33: =+C87 -> Car.gr | L33: =+L87*1000 -> 1200
C34: Marketplaces: listings per channel (istant)
C35: Marketplace | D35: Segment | E35: Product | F35: Car type | G35: Channel | H35: Item | I35: UoM | J35: 2024 | K35: % | L35: 2030 | O35: Notes/ source
C36: Car.gr | D36: Retail | E36: Loan | F36: Used | G36: Total | H36: Car listings | I36: # k | J36: 135 | K36: =J36/$J$36 -> 1 | L36: 180
C37: Car.gr | D37: Retail | E37: Loan | F37: Used | G37: B2C | H37: Car listings | I37: # k | J37: 75 | K37: =J37/$J$36 -> 0.55555556 | L37: =K37*$L$36 -> 100
C38: Car.gr | D38: Retail | E38: Loan | F38: Used | G38: C2C | H38: Car listings | I38: # k | J38: 60 | K38: =J38/$J$36 -> 0.44444444 | L38: =K38*$L$36 -> 80
C39: Cardom | D39: Retail | E39: Loan | F39: Used | G39: B2C | H39: Car listings | I39: # k | J39: 0.24 | K39: 1 | L39: =J39*(1+$L$40)^6 -> 0.42108654
C40: Cardom | D40: Retail | E40: Loan | F40: Used | G40: Total | H40: 2024-2030 CAGR | I40: % | L40: =_xlfn.RRI(L35-J35,J36,L36)*2 -> 0.098230127 | O40: Assuming Cardom will grow double vs. Car.gr as it is a newly established marketplace
C42: Marketplaces: listings per channel (yearly)
C44: Marketplace | D44: Segment | E44: Product | F44: Car type | G44: Channel | H44: Item | I44: UoM | J44: 2024 | K44: % | L44: 2030 | O44: Notes/ source
C45: Car.gr | D45: Retail | E45: Loan | F45: Used | G45: Total | H45: Car listings | I45: # k | J45: =J36 -> 135 | K45: =J45/$J$45 -> 1 | L45: =L36 -> 180 | O45: Adjustment for average listing rotation is not applied, as the total number of listings includes older inventory. It is assumed that Car.gr provides a comprehensive snapshot, reflecting the entire used car market.
...

Sheet summary for tab 4.
B2: Car.gr – Retail – Used – Total – Cars financed
B3: 2024 → 2k
B4: 2030 → 6k
B6: Car.gr – Retail – Auto loan – Used – B2C – Cars financed
B7: 2024 → 1,1k
B8: 2030 → 4k
B11: Car.gr – Retail – Cash loan – Used – C2C – Cars financed
B12: 2024 → 0,9k
B13: 2030 → 2k

Sheet p&l
B2: Increase used car financing
B3: Desc. | C3: Desc. Figures | D3: Y1 | E3: Y2 | F3: Y3 | G3: Y4 | H3: Y5
B4: Market total
B5: car financed | C5: Market # of New cars financed
C6: Market # of Used cars financed
C7: ERB # of New cars financed
C8: ERB # of Used cars financed
B9: disbursed amount | C9: Market total disbursed amount New cars
C10: Market total disbursed amount Used cars
C11: ERB total disbursed amount New cars
C12: ERB total disbursed amount Used cars
B13: (RAR) | C13: RAR New cars
C14: RAR Used cars
B15: (Opex) | C15: Opex New cars
C16: Opex Used cars
B17: (PBT) | C17: PBT New cars
C18: PBT Used cars
B19: (Capex) | C19: capex New cars
C20: capex Used cars
B22: Redesign end-to-end B2B offering - B2B
B23: Desc. | C23: Desc. Figures | D23: Y1 | E23: Y2 | F23: Y3 | G23: Y4 | H23: Y5
B24: New cars (# of cars and disbursed amounts) | C24: Market # of New cars financed
C25: Market # of Used cars financed
C26: ERB # of New cars financed
C27: ERB # of Used cars financed
B28: Used cars (# of cars and disbursed amounts) | C28: Market total disbursed amount New cars
C29: Market total disbursed amount Used cars
C30: ERB total disbursed amount New cars
C31: ERB total disbursed amount Used cars
B32: (RAR) | C32: RAR New cars
C33: RAR Used cars
B34: (Opex) | C34: Opex New cars
C35: Opex Used cars
B36: (PBT) | C36: PBT New cars
C37: PBT Used cars
B38: (Capex) | C38: capex New cars
C39: capex Used cars
B41: Redesign end-to-end B2B offering - RETAIL
B42: Desc. | C42: Desc. Figures | D42: Y1 | E42: Y2 | F42: Y3 | G42: Y4 | H42: Y5
B43: New cars (# of cars and disbursed amounts) | C43: Market # of New cars financed
...

Sheet B2B financing market
B2: 1. Avg. yearly stock, by segment
D3: 2024 | E3: 2030 | F3: 2030 | J3: 2030
B4: Segment | C4: Car type | D4: Car sold to end customers, yearly | E4: Car sold to end customers, yearly | F4: Car sold to end customers, monthly | G4: Avg. stock Rotation, per year | H4: Avg. Yearly stock, k# | I4: Financing penetration, % | J4: Car volumes financed, k# | K4: Yearly target for retail, % | L4: Yearly target for SB, % | M4: Yearly target for retail, #k | N4: Yearly target for retail, #k | O4: Notes
B5: in k#
A6: =B6&C6 -> DealerNew Auto | B6: Dealer | C6: New Auto | D6: 62 | E6: 74 | F6: =E6/12 -> 6.1666667 | G6: =360/60 -> 6 | H6: =E6/G6 -> 12.333333 | I6: 0.9 | J6: =(E6)*I6 -> 66.6 | K6: 1 | M6: =J6*K6 -> 66.6 | N6: =K6*L6 -> 0 | O6: Assuming stable inventory; stock rotation: 365/days supply
A7: =B7&C7 -> DealerUsed Auto | B7: Dealer | C7: Used Auto | D7: 68 | E7: 90 | F7: =E7/12 -> 7.5 | G7: =365/45 -> 8.1111111 | H7: =E7/G7 -> 11.09589 | I7: 0.9 | J7: =(E7)*I7 -> 81 | K7: 1 | M7: =J7*K7 -> 81 | N7: =K7*L7 -> 0 | O7: Assuming stable inventory; stock rotation: 365/days supply
A8: =B8&C8 -> Independent dealersNew Auto | B8: Independent dealers | C8: New Auto | D8: =85%*D6 -> 52.7 | E8: =85%*E6 -> 62.9 | G8: =360/60 -> 6 | H8: =E8/G8 -> 10.483333 | I8: 0.9 | J8: =(E8)*I8 -> 56.61
A9: =B9&C9 -> Independent dealersUsed Auto | B9: Independent dealers | C9: Used Auto | D9: =85%*D7 -> 57.8 | E9: =85%*E7 -> 76.5 | G9: =365/45 -> 8.1111111 | H9: =E9/G9 -> 9.4315068 | I9: 0.9 | J9: =(E9)*I9 -> 68.85
A10: =B10&C10 -> Dealers with OEMs captivesNew Auto | B10: Dealers with OEMs captives | C10: New Auto | D10: =D6-D8 -> 9.3 | E10: =E6-E8 -> 11.1 | G10: =360/60 -> 6 | H10: =E10/G10 -> 1.85 | I10: 0.9 | J10: =(E10)*I10 -> 9.99
A11: =B11&C11 -> Dealers with OEMs captivesUsed Auto | B11: Dealers with OEMs captives | C11: Used Auto | D11: =D7-D9 -> 10.2 | E11: =E7-E9 -> 13.5 | G11: =365/45 -> 8.1111111 | H11: =E11/G11 -> 1.6643836 | I11: 0.9 | J11: =(E11)*I11 -> 12.15
A12: =B12&C12 -> LeaseCosNew Auto | B12: LeaseCos | C12: New Auto | D12: 45 | E12: 54 | F12: =E12/12 -> 4.5 | I12: 0.85 | J12: =(E12)*I12 -> 45.9 | L12: 0.2 | M12: =J12*K12 -> 0 | N12: =K12*L12 -> 0 | O12: ERB Leasing
A13: =B13&C13 -> LeaseCosUsed Auto | B13: LeaseCos | C13: Used Auto | D13: 0 | E13: 0 | F13: =E13/12 -> 0 | I13: 0.85 | J13: =(E13)*I13 -> 0 | L13: 0.2 | M13: =J13*K13 -> 0 | N13: =K13*L13 -> 0 | O13: ERB Leasing
A14: =B14&C14 -> RACNew Auto | B14: RAC | C14: New Auto | D14: 26 | E14: 31 | F14: =E14/12 -> 2.5833333 | I14: 0.8 | J14: =(E14)*I14 -> 24.8 | L14: 0.3 | M14: =J14*K14 -> 0 | N14: =K14*L14 -> 0
A15: =B15&C15 -> RACUsed Auto | B15: RAC | C15: Used Auto | D15: 14 | E15: 16 | F15: =E15/12 -> 1.3333333 | I15: 0.8 | J15: =(E15)*I15 -> 12.8 | L15: 0.3 | M15: =J15*K15 -> 0 | N15: =K15*L15 -> 0
A16: small | B16: RAC | C16: New Auto | D16: =ROUND(30%*D14,0) -> 8 | F16: =E16/12 -> 0 | G16: =360/30 -> 12 | I16: 0.35 | J16: =(E16)*I16 -> 0 | M16: =J16*K16 -> 0 | N16: =K16*L16 -> 0
A17: small | B17: RAC | C17: Used Auto | D17: =ROUND(30%*D15,0) -> 4 | F17: =E17/12 -> 0 | G17: =360/30 -> 12 | I17: 0.35 | J17: =(E17)*I17 -> 0 | M17: =J17*K17 -> 0 | N17: =K17*L17 -> 0
B18: Direct corp | C18: New Auto | D18: 4 | E18: 4 | F18: =E18/12 -> 0.33333333 | I18: 0.2
B19: Direct corp | C19: Used Auto | D19: 2 | E19: 2 | F19: =E19/12 -> 0.16666667 | I19: 0.2
B20: Total | D20: =SUM(D12:D19) -> 103 | E20: =SUM(E12:E19) -> 107 | F20: =SUM(F12:F19) -> 8.9166667 | H20: =SUM(H6:H19) -> 46.858447 | J20: =SUM(J8:J19) -> 231.1 | M20: =SUM(M12:M19) -> 0 | N20: =SUM(N12:N19) -> 0
B22: 2024 | C22: Customer view | D22: Customer view | E22: Dealer view | F22: Dealer view
B23: Product | C23: New Auto | D23: Used Auto | E23: New Auto | F23: Used Auto | G23: notes
B24: in €
B25: Auto loan | C25: 15000 | D25: 9500 | E25: =C25/(1+30%) -> 11538.462 | F25: =D25/(1+30%) -> 7307.6923 | G25: Considering 30%% markup
B26: Floor plan | C26: 0 | D26: 5000 | E26: =C26/(1+30%) -> 0 | F26: =D26/(1+30%) -> 3846.1538 | G26: Considering 30%% markup
B27: Stock finance
B28: Leasing | C28: 25000 | D28: 13000 | E28: =C28/(1+30%) -> 19230.769 | F28: =D28/(1+30%) -> 10000 | G28: Considering 30%% markup
B29: Other | E29: =C29/(1+30%) -> 0 | F29: =D29/(1+30%) -> 0 | G29: Considering 30%% markup
B31: 2. Product mix, %
C32: 2024
B33: Product | C33: Car type | D33: Segment | G33: Notes
B34: in % | D34: LeaseCos | E34: RAC | F34: Independent dealers | G34: Dealers with OEMs captives
A35: =B35&C35 -> Floor planNew Auto | B35: Floor plan | C35: New Auto | D35: 0 | E35: 0 | F35: 0.4 | G35: 0.7 | H35: Only Toyota, Mercedez and small syngelidis group brands have floor plan (only 1 brand)
A36: =B36&C36 -> Floor planUsed Auto | B36: Floor plan | C36: Used Auto | D36: 0 | E36: 0 | F36: 0 | G36: 0.4
A37: =B37&C37 -> Stock financeNew Auto | B37: Stock finance | C37: New Auto | D37: 0 | E37: 0 | F37: 0.15 | G37: 0.05
A38: =B38&C38 -> Stock financeUsed Auto | B38: Stock finance | C38: Used Auto | D38: 0 | E38: 0 | F38: 0.25 | G38: 0.05
A39: =B39&C39 -> LoanNew Auto | B39: Loan | C39: New Auto | D39: 0.3 | E39: 0.25 | F39: 0.15 | G39: 0.05
A40: =B40&C40 -> LoanUsed Auto | B40: Loan | C40: Used Auto | D40: 0 | E40: 0.4 | F40: 0.4 | G40: 0.3
A41: =B41&C41 -> Financial leaseNew Auto | B41: Financial lease | C41: New Auto | D41: 0.6 | E41: 0.5 | F41: 0.15 | G41: 0
A42: =B42&C42 -> Financial leaseUsed Auto | B42: Financial lease | C42: Used Auto | D42: 0 | E42: 0.2 | F42: 0 | G42: 0
A43: =B43&C43 -> Operational leaseNew Auto | B43: Operational lease | C43: New Auto | D43: 0 | E43: 0 | F43: 0 | G43: 0
...

Sheet B2B financing opportunity
B2: B2B Financing Opportunities: Target Wholesalers for Eurobank by 2030
B4: Product | C4: Importer | D4: Number of dealers | E4: Yearly number of cars sold | F4: Total line value | G4: Yearly cars financed | H4: Avg. Car value | I4: RAR per car | J4: Annual RAR | K4: Assumption for selecting the importer | L4: Notes
B5: Unit of measure | D5: # | E5: # | F5: €M | G5: # | H5: € | I5: € | J5: €
B6: Floor plan | C6: Toyota | D6: 20 | F6: 15
B7: Floor plan
B8: Floor plan
B9: Floor plan
B10: Floor plan
B11: Floor plan
B12: Floor plan
B13: Floor plan
B14: Floor plan
B15: Floor plan
B16: Floor plan
B17: Floor plan
B18: Floor plan
... B20: Floor plan
B23: Product | C23: Dealer Group | D23: Number of dealers | E23: Yearly number of cars sold | F23: Total line value | G23: Yearly cars financed | H23: Avg. Car value | I23: RAR per car | J23: Annual RAR | K23: Assumption for selecting the dealer | L23: Notes
B24: Unit of measure | D24: # | E24: # | F24: €M | G24: # | H24: € | I24: € | J24: €
B25: Stock finance
B26: Stock finance
B27: Stock finance
B28: Stock finance
B29: Stock finance
B30: Stock finance
B31: Stock finance
B32: Stock finance
B33: Stock finance
B34: Stock finance
B35: Stock finance
B36: Stock finance
... B39: Stock finance
B43: Product | C43: Fleet Group | D43: Number of dealers | E43: Yearly number of cars sold | F43: Total line value | G43: Yearly cars financed | H43: Avg. Car value | I43: RAR per car | J43: Annual RAR | K43: Assumption for selecting the dealer | L43: Notes
B44: Unit of measure | D44: # | E44: # | F44: €M | G44: # | H44: € | I44: € | J44: €
B45: Fleet financing
B46: Fleet financing
B47: Fleet financing
B48: Fleet financing
B49: Fleet financing
B50: Fleet financing
...
