Workbook
Name Balance: OFFSET(Sheet1!$E$11,0,0,COUNT(Sheet1!$E$11:$E$40,">0"),1)
Name Holiday: '[1]Bill Payment and Holidays'!$K$8:$K$26
Name Inte: OFFSET(Sheet1!$D$11,0,0,COUNT(Sheet1!$D$11:$D$40,">0"),1)
Name Interest: OFFSET(Sheet1!$C$11,0,0,COUNT(Sheet1!$C$11:$C$40,">0"),1)
Name Principal: OFFSET(Sheet1!$B$11,0,0,COUNT(Sheet1!$B$11:$B$40,">0"),1)
Name YearPeriod: '[1]Bill Payment and Holidays'!$O$3:$O$368

Sheet Sheet1
G3: ='Amortization Chart'!E5 -> 25000
G4: ='Amortization Chart'!E6 -> 9 | H4: %
G5: ='Amortization Chart'!E7 -> 48
G6: ='Amortization Chart'!E8 -> 45658
G7: ='Amortization Chart'!U7 -> 622.12606
A10: Year | B10: Principal Paid | C10: Interest Paid | D10: Int | E10: Principal Balance
A11: 1 | B11: =SUM(K11:K22) -> 5436.123 | C11: =SUM(L11:L22) -> 2029.3897 | D11: =IF(E11="","",IF(B11<C11,B11,0)) -> 0 | E11: =J22 -> 19563.877 | I11: =IF(G5<>"",1,"") -> 1 | J11: =IF(I11<>"",G3-K11,"") -> 24565.374 | K11: =IF(I11<>"",M11-L11,"") -> 434.62606 | L11: =IF(I11<>"",G3*G4/12/100,"") -> 187.5 | M11: =IF(I11<>"",G7,"") -> 622.12606 | N11: =IF(I11<>"",L11,"") -> 187.5 | P11: 1
A12: 2 | B12: =IF(E12="","",SUM(OFFSET($K$11:$K$22,ROW(A1)*12,0))) -> 5946.0688 | C12: =IF(E12="","",SUM(OFFSET($L$11:$L$22,ROW(A1)*12,0))) -> 1519.4439 | D12: =IF(E12="","",IF(B12<C12,B12,NA())) -> #N/A | E12: =OFFSET($J$10,ROW(A2)*12,0) -> 13617.808 | I12: =IF(OR(I11=$G$5,I11=""),"",I11+1) -> 2 | J12: =IF(I12<>"",J11-K12,"") -> 24127.488 | K12: =IF(I12<>"",M12-L12,"") -> 437.88575 | L12: =IF(I12<>"",J11*$G$4/12/100,"") -> 184.2403 | M12: =IF(I12<>"",M11,"") -> 622.12606 | N12: =IF(I12<>"",L12+N11,"") -> 371.7403 | P12: 2
A13: 3 | B13: =IF(E13="","",SUM(OFFSET($K$11:$K$22,ROW(A2)*12,0))) -> 6503.8511 | C13: =IF(E13="","",SUM(OFFSET($L$11:$L$22,ROW(A2)*12,0))) -> 961.66164 | D13: =IF(E13="","",IF(B13<C13,B13,NA())) -> #N/A | E13: =OFFSET($J$10,ROW(A3)*12,0) -> 7113.9572 | I13: =IF(OR(I12=$G$5,I12=""),"",I12+1) -> 3 | J13: =IF(I13<>"",J12-K13,"") -> 23686.318 | K13: =IF(I13<>"",M13-L13,"") -> 441.1699 | L13: =IF(I13<>"",J12*$G$4/12/100,"") -> 180.95616 | M13: =IF(I13<>"",M12,"") -> 622.12606 | N13: =IF(I13<>"",L13+N12,"") -> 552.69647 | P13: 3
A14: 4 | B14: =IF(E14="","",SUM(OFFSET($K$11:$K$22,ROW(A3)*12,0))) -> 7113.9572 | C14: =IF(E14="","",SUM(OFFSET($L$11:$L$22,ROW(A3)*12,0))) -> 351.55555 | D14: =IF(E14="","",IF(B14<C14,B14,NA())) -> #N/A | E14: =OFFSET($J$10,ROW(A4)*12,0) -> -1.0459189e-11 | I14: =IF(OR(I13=$G$5,I13=""),"",I13+1) -> 4 | J14: =IF(I14<>"",J13-K14,"") -> 23241.84 | K14: =IF(I14<>"",M14-L14,"") -> 444.47867 | L14: =IF(I14<>"",J13*$G$4/12/100,"") -> 177.64739 | M14: =IF(I14<>"",M13,"") -> 622.12606 | N14: =IF(I14<>"",L14+N13,"") -> 730.34385 | P14: 4
A15: 5 | B15: =IF(E15="","",SUM(OFFSET($K$11:$K$22,ROW(A4)*12,0))) | C15: =IF(E15="","",SUM(OFFSET($L$11:$L$22,ROW(A4)*12,0))) | D15: =IF(E15="","",IF(B15<C15,B15,NA())) | E15: =OFFSET($J$10,ROW(A5)*12,0) | I15: =IF(OR(I14=$G$5,I14=""),"",I14+1) -> 5 | J15: =IF(I15<>"",J14-K15,"") -> 22794.027 | K15: =IF(I15<>"",M15-L15,"") -> 447.81226 | L15: =IF(I15<>"",J14*$G$4/12/100,"") -> 174.3138 | M15: =IF(I15<>"",M14,"") -> 622.12606 | N15: =IF(I15<>"",L15+N14,"") -> 904.65765 | P15: 5
A16: 6 | B16: =IF(E16="","",SUM(OFFSET($K$11:$K$22,ROW(A5)*12,0))) | C16: =IF(E16="","",SUM(OFFSET($L$11:$L$22,ROW(A5)*12,0))) | D16: =IF(E16="","",IF(B16<C16,B16,NA())) | E16: =OFFSET($J$10,ROW(A6)*12,0) | I16: =IF(OR(I15=$G$5,I15=""),"",I15+1) -> 6 | J16: =IF(I16<>"",J15-K16,"") -> 22342.856 | K16: =IF(I16<>"",M16-L16,"") -> 451.17085 | L16: =IF(I16<>"",J15*$G$4/12/100,"") -> 170.95521 | M16: =IF(I16<>"",M15,"") -> 622.12606 | N16: =IF(I16<>"",L16+N15,"") -> 1075.6129 | P16: 6
A17: 7 | B17: =IF(E17="","",SUM(OFFSET($K$11:$K$22,ROW(A6)*12,0))) | C17: =IF(E17="","",SUM(OFFSET($L$11:$L$22,ROW(A6)*12,0))) | D17: =IF(E17="","",IF(B17<C17,B17,NA())) | E17: =OFFSET($J$10,ROW(A7)*12,0) | I17: =IF(OR(I16=$G$5,I16=""),"",I16+1) -> 7 | J17: =IF(I17<>"",J16-K17,"") -> 21888.302 | K17: =IF(I17<>"",M17-L17,"") -> 454.55464 | L17: =IF(I17<>"",J16*$G$4/12/100,"") -> 167.57142 | M17: =IF(I17<>"",M16,"") -> 622.12606 | N17: =IF(I17<>"",L17+N16,"") -> 1243.1843 | P17: 7
A18: 8 | B18: =IF(E18="","",SUM(OFFSET($K$11:$K$22,ROW(A7)*12,0))) | C18: =IF(E18="","",SUM(OFFSET($L$11:$L$22,ROW(A7)*12,0))) | D18: =IF(E18="","",IF(B18<C18,B18,NA())) | E18: =OFFSET($J$10,ROW(A8)*12,0) | I18: =IF(OR(I17=$G$5,I17=""),"",I17+1) -> 8 | J18: =IF(I18<>"",J17-K18,"") -> 21430.338 | K18: =IF(I18<>"",M18-L18,"") -> 457.9638 | L18: =IF(I18<>"",J17*$G$4/12/100,"") -> 164.16226 | M18: =IF(I18<>"",M17,"") -> 622.12606 | N18: =IF(I18<>"",L18+N17,"") -> 1407.3465 | P18: 8
A19: 9 | B19: =IF(E19="","",SUM(OFFSET($K$11:$K$22,ROW(A8)*12,0))) | C19: =IF(E19="","",SUM(OFFSET($L$11:$L$22,ROW(A8)*12,0))) | D19: =IF(E19="","",IF(B19<C19,B19,NA())) | E19: =OFFSET($J$10,ROW(A9)*12,0) | I19: =IF(OR(I18=$G$5,I18=""),"",I18+1) -> 9 | J19: =IF(I19<>"",J18-K19,"") -> 20968.94 | K19: =IF(I19<>"",M19-L19,"") -> 461.39852 | L19: =IF(I19<>"",J18*$G$4/12/100,"") -> 160.72754 | M19: =IF(I19<>"",M18,"") -> 622.12606 | N19: =IF(I19<>"",L19+N18,"") -> 1568.0741 | P19: 9
A20: 10 | B20: =IF(E20="","",SUM(OFFSET($K$11:$K$22,ROW(A9)*12,0))) | C20: =IF(E20="","",SUM(OFFSET($L$11:$L$22,ROW(A9)*12,0))) | D20: =IF(E20="","",IF(B20<C20,B20,NA())) | E20: =OFFSET($J$10,ROW(A10)*12,0) | I20: =IF(OR(I19=$G$5,I19=""),"",I19+1) -> 10 | J20: =IF(I20<>"",J19-K20,"") -> 20504.081 | K20: =IF(I20<>"",M20-L20,"") -> 464.85901 | L20: =IF(I20<>"",J19*$G$4/12/100,"") -> 157.26705 | M20: =IF(I20<>"",M19,"") -> 622.12606 | N20: =IF(I20<>"",L20+N19,"") -> 1725.3411 | P20: 10
A21: 11 | B21: =IF(E21="","",SUM(OFFSET($K$11:$K$22,ROW(A10)*12,0))) | C21: =IF(E21="","",SUM(OFFSET($L$11:$L$22,ROW(A10)*12,0))) | D21: =IF(E21="","",IF(B21<C21,B21,NA())) | E21: =OFFSET($J$10,ROW(A11)*12,0) | I21: =IF(OR(I20=$G$5,I20=""),"",I20+1) -> 11 | J21: =IF(I21<>"",J20-K21,"") -> 20035.735 | K21: =IF(I21<>"",M21-L21,"") -> 468.34546 | L21: =IF(I21<>"",J20*$G$4/12/100,"") -> 153.7806 | M21: =IF(I21<>"",M20,"") -> 622.12606 | N21: =IF(I21<>"",L21+N20,"") -> 1879.1217 | P21: 11
A22: 12 | B22: =IF(E22="","",SUM(OFFSET($K$11:$K$22,ROW(A11)*12,0))) | C22: =IF(E22="","",SUM(OFFSET($L$11:$L$22,ROW(A11)*12,0))) | D22: =IF(E22="","",IF(B22<C22,B22,NA())) | E22: =OFFSET($J$10,ROW(A12)*12,0) | I22: =IF(OR(I21=$G$5,I21=""),"",I21+1) -> 12 | J22: =IF(I22<>"",J21-K22,"") -> 19563.877 | K22: =IF(I22<>"",M22-L22,"") -> 471.85805 | L22: =IF(I22<>"",J21*$G$4/12/100,"") -> 150.26801 | M22: =IF(I22<>"",M21,"") -> 622.12606 | N22: =IF(I22<>"",L22+N21,"") -> 2029.3897 | P22: 12
A23: 13 | B23: =IF(E23="","",SUM(OFFSET($K$11:$K$22,ROW(A12)*12,0))) | C23: =IF(E23="","",SUM(OFFSET($L$11:$L$22,ROW(A12)*12,0))) | D23: =IF(E23="","",IF(B23<C23,B23,NA())) | E23: =OFFSET($J$10,ROW(A13)*12,0) | I23: =IF(OR(I22=$G$5,I22=""),"",I22+1) -> 13 | J23: =IF(I23<>"",J22-K23,"") -> 19088.48 | K23: =IF(I23<>"",M23-L23,"") -> 475.39698 | L23: =IF(I23<>"",J22*$G$4/12/100,"") -> 146.72908 | M23: =IF(I23<>"",M22,"") -> 622.12606 | N23: =IF(I23<>"",L23+N22,"") -> 2176.1188 | P23: 13
... A40: 30 | B40: =IF(E40="","",SUM(OFFSET($K$11:$K$22,ROW(A29)*12,0))) | C40: =IF(E40="","",SUM(OFFSET($L$11:$L$22,ROW(A29)*12,0))) | D40: =IF(E40="","",IF(B40<C40,B40,NA())) | E40: =OFFSET($J$10,ROW(A30)*12,0) | I40: =IF(OR(I39=$G$5,I39=""),"",I39+1) -> 30 | J40: =IF(I40<>"",J39-K40,"") -> 10438.766 | K40: =IF(I40<>"",M40-L40,"") -> 539.78691 | L40: =IF(I40<>"",J39*$G$4/12/100,"") -> 82.339145 | M40: =IF(I40<>"",M39,"") -> 622.12606 | N40: =IF(I40<>"",L40+N39,"") -> 4102.5476 | P40: 30
I41: =IF(OR(I40=$G$5,I40=""),"",I40+1) -> 31 | J41: =IF(I41<>"",J40-K41,"") -> 9894.9305 | K41: =IF(I41<>"",M41-L41,"") -> 543.83532 | L41: =IF(I41<>"",J40*$G$4/12/100,"") -> 78.290743 | M41: =IF(I41<>"",M40,"") -> 622.12606 | N41: =IF(I41<>"",L41+N40,"") -> 4180.8383
I42: =IF(OR(I41=$G$5,I41=""),"",I41+1) -> 32 | J42: =IF(I42<>"",J41-K42,"") -> 9347.0164 | K42: =IF(I42<>"",M42-L42,"") -> 547.91408 | L42: =IF(I42<>"",J41*$G$4/12/100,"") -> 74.211979 | M42: =IF(I42<>"",M41,"") -> 622.12606 | N42: =IF(I42<>"",L42+N41,"") -> 4255.0503
I43: =IF(OR(I42=$G$5,I42=""),"",I42+1) -> 33 | J43: =IF(I43<>"",J42-K43,"") -> 8794.993 | K43: =IF(I43<>"",M43-L43,"") -> 552.02344 | L43: =IF(I43<>"",J42*$G$4/12/100,"") -> 70.102623 | M43: =IF(I43<>"",M42,"") -> 622.12606 | N43: =IF(I43<>"",L43+N42,"") -> 4325.1529
I44: =IF(OR(I43=$G$5,I43=""),"",I43+1) -> 34 | J44: =IF(I44<>"",J43-K44,"") -> 8238.8294 | K44: =IF(I44<>"",M44-L44,"") -> 556.16361 | L44: =IF(I44<>"",J43*$G$4/12/100,"") -> 65.962447 | M44: =IF(I44<>"",M43,"") -> 622.12606 | N44: =IF(I44<>"",L44+N43,"") -> 4391.1154
I45: =IF(OR(I44=$G$5,I44=""),"",I44+1) -> 35 | J45: =IF(I45<>"",J44-K45,"") -> 7678.4945 | K45: =IF(I45<>"",M45-L45,"") -> 560.33484 | L45: =IF(I45<>"",J44*$G$4/12/100,"") -> 61.79122 | M45: =IF(I45<>"",M44,"") -> 622.12606 | N45: =IF(I45<>"",L45+N44,"") -> 4452.9066
I46: =IF(OR(I45=$G$5,I45=""),"",I45+1) -> 36 | J46: =IF(I46<>"",J45-K46,"") -> 7113.9572 | K46: =IF(I46<>"",M46-L46,"") -> 564.53735 | L46: =IF(I46<>"",J45*$G$4/12/100,"") -> 57.588709 | M46: =IF(I46<>"",M45,"") -> 622.12606 | N46: =IF(I46<>"",L46+N45,"") -> 4510.4953
I47: =IF(OR(I46=$G$5,I46=""),"",I46+1) -> 37 | J47: =IF(I47<>"",J46-K47,"") -> 6545.1858 | K47: =IF(I47<>"",M47-L47,"") -> 568.77138 | L47: =IF(I47<>"",J46*$G$4/12/100,"") -> 53.354679 | M47: =IF(I47<>"",M46,"") -> 622.12606 | N47: =IF(I47<>"",L47+N46,"") -> 4563.85
I48: =IF(OR(I47=$G$5,I47=""),"",I47+1) -> 38 | J48: =IF(I48<>"",J47-K48,"") -> 5972.1486 | K48: =IF(I48<>"",M48-L48,"") -> 573.03717 | L48: =IF(I48<>"",J47*$G$4/12/100,"") -> 49.088893 | M48: =IF(I48<>"",M47,"") -> 622.12606 | N48: =IF(I48<>"",L48+N47,"") -> 4612.9389
I49: =IF(OR(I48=$G$5,I48=""),"",I48+1) -> 39 | J49: =IF(I49<>"",J48-K49,"") -> 5394.8137 | K49: =IF(I49<>"",M49-L49,"") -> 577.33494 | L49: =IF(I49<>"",J48*$G$4/12/100,"") -> 44.791115 | M49: =IF(I49<>"",M48,"") -> 622.12606 | N49: =IF(I49<>"",L49+N48,"") -> 4657.73
I50: =IF(OR(I49=$G$5,I49=""),"",I49+1) -> 40 | J50: =IF(I50<>"",J49-K50,"") -> 4813.1487 | K50: =IF(I50<>"",M50-L50,"") -> 581.66496 | L50: =IF(I50<>"",J49*$G$4/12/100,"") -> 40.461103 | M50: =IF(I50<>"",M49,"") -> 622.12606 | N50: =IF(I50<>"",L50+N49,"") -> 4698.1911
I51: =IF(OR(I50=$G$5,I50=""),"",I50+1) -> 41 | J51: =IF(I51<>"",J50-K51,"") -> 4227.1213 | K51: =IF(I51<>"",M51-L51,"") -> 586.02744 | L51: =IF(I51<>"",J50*$G$4/12/100,"") -> 36.098615 | M51: =IF(I51<>"",M50,"") -> 622.12606 | N51: =IF(I51<>"",L51+N50,"") -> 4734.2897
I52: =IF(OR(I51=$G$5,I51=""),"",I51+1) -> 42 | J52: =IF(I52<>"",J51-K52,"") -> 3636.6986 | K52: =IF(I52<>"",M52-L52,"") -> 590.42265 | L52: =IF(I52<>"",J51*$G$4/12/100,"") -> 31.70341 | M52: =IF(I52<>"",M51,"") -> 622.12606 | N52: =IF(I52<>"",L52+N51,"") -> 4765.9931
... I370: =IF(OR(I369=$G$5,I369=""),"",I369+1) | J370: =IF(I370<>"",J369-K370,"") | K370: =IF(I370<>"",M370-L370,"") | L370: =IF(I370<>"",J369*$G$4/12/100,"") | M370: =IF(I370<>"",M369,"") | N370: =IF(I370<>"",L370+N369,"")

Sheet Amortization Chart
B1: Loan Amortization vs Car Value depreciation
B3: Data | H3: Chart | U3: Summary
B5: Loan Amount | D5: EURO | E5: 25000 | U5: Monthly Payment
B6: Interest Rate | D6: % / Year | E6: 9 | U6: (Principal + Interest)
B7: Term | D7: Month | E7: 48 | U7: =IF(OR(E5="",E6="",E7=""),"",-PMT(E6/1200,E7,E5)) -> 622.12606
B8: Payment Start Date | E8: 45658
B10: Table | U10: Total Payment
B11: 1 | U11: =U7*E7 -> 29862.051
B12: Month | C12: Balance | D12: Principal | E12: Interest
B13: =IF(B11>(MAX(Sheet1!I11:I370)-11),(MAX(Sheet1!I11:I370)-11),B11) -> 1 | C13: =VLOOKUP($B13,Sheet1!$I$11:$N$370,2,FALSE) -> 24565.374 | D13: =VLOOKUP($B13,Sheet1!$I$11:$N$370,3,FALSE) -> 434.62606 | E13: =VLOOKUP($B13,Sheet1!$I$11:$N$370,4,FALSE) -> 187.5
B14: =B13+1 -> 2 | C14: =VLOOKUP($B14,Sheet1!$I$11:$N$370,2,FALSE) -> 24127.488 | D14: =VLOOKUP($B14,Sheet1!$I$11:$N$370,3,FALSE) -> 437.88575 | E14: =VLOOKUP($B14,Sheet1!$I$11:$N$370,4,FALSE) -> 184.2403
B15: =B14+1 -> 3 | C15: =VLOOKUP($B15,Sheet1!$I$11:$N$370,2,FALSE) -> 23686.318 | D15: =VLOOKUP($B15,Sheet1!$I$11:$N$370,3,FALSE) -> 441.1699 | E15: =VLOOKUP($B15,Sheet1!$I$11:$N$370,4,FALSE) -> 180.95616 | U15: Payoff Date
B16: =B15+1 -> 4 | C16: =VLOOKUP($B16,Sheet1!$I$11:$N$370,2,FALSE) -> 23241.84 | D16: =VLOOKUP($B16,Sheet1!$I$11:$N$370,3,FALSE) -> 444.47867 | E16: =VLOOKUP($B16,Sheet1!$I$11:$N$370,4,FALSE) -> 177.64739 | U16: =DATE(YEAR(E8),MONTH(E8)+E7,DAY(E8)) -> 47119
B17: =B16+1 -> 5 | C17: =VLOOKUP($B17,Sheet1!$I$11:$N$370,2,FALSE) -> 22794.027 | D17: =VLOOKUP($B17,Sheet1!$I$11:$N$370,3,FALSE) -> 447.81226 | E17: =VLOOKUP($B17,Sheet1!$I$11:$N$370,4,FALSE) -> 174.3138
B18: =B17+1 -> 6 | C18: =VLOOKUP($B18,Sheet1!$I$11:$N$370,2,FALSE) -> 22342.856 | D18: =VLOOKUP($B18,Sheet1!$I$11:$N$370,3,FALSE) -> 451.17085 | E18: =VLOOKUP($B18,Sheet1!$I$11:$N$370,4,FALSE) -> 170.95521
B19: =B18+1 -> 7 | C19: =VLOOKUP($B19,Sheet1!$I$11:$N$370,2,FALSE) -> 21888.302 | D19: =VLOOKUP($B19,Sheet1!$I$11:$N$370,3,FALSE) -> 454.55464 | E19: =VLOOKUP($B19,Sheet1!$I$11:$N$370,4,FALSE) -> 167.57142 | U19: Interest amount
B20: =B19+1 -> 8 | C20: =VLOOKUP($B20,Sheet1!$I$11:$N$370,2,FALSE) -> 21430.338 | D20: =VLOOKUP($B20,Sheet1!$I$11:$N$370,3,FALSE) -> 457.9638 | E20: =VLOOKUP($B20,Sheet1!$I$11:$N$370,4,FALSE) -> 164.16226 | U20: =+U11-E5 -> 4862.0508
B21: =B20+1 -> 9 | C21: =VLOOKUP($B21,Sheet1!$I$11:$N$370,2,FALSE) -> 20968.94 | D21: =VLOOKUP($B21,Sheet1!$I$11:$N$370,3,FALSE) -> 461.39852 | E21: =VLOOKUP($B21,Sheet1!$I$11:$N$370,4,FALSE) -> 160.72754
B22: =B21+1 -> 10 | C22: =VLOOKUP($B22,Sheet1!$I$11:$N$370,2,FALSE) -> 20504.081 | D22: =VLOOKUP($B22,Sheet1!$I$11:$N$370,3,FALSE) -> 464.85901 | E22: =VLOOKUP($B22,Sheet1!$I$11:$N$370,4,FALSE) -> 157.26705
B23: =B22+1 -> 11 | C23: =VLOOKUP($B23,Sheet1!$I$11:$N$370,2,FALSE) -> 20035.735 | D23: =VLOOKUP($B23,Sheet1!$I$11:$N$370,3,FALSE) -> 468.34546 | E23: =VLOOKUP($B23,Sheet1!$I$11:$N$370,4,FALSE) -> 153.7806
B24: =B23+1 -> 12 | C24: =VLOOKUP($B24,Sheet1!$I$11:$N$370,2,FALSE) -> 19563.877 | D24: =VLOOKUP($B24,Sheet1!$I$11:$N$370,3,FALSE) -> 471.85805 | E24: =VLOOKUP($B24,Sheet1!$I$11:$N$370,4,FALSE) -> 150.26801
E29: =+E5 -> 25000
D30: Y1 | E30: =SUM(E35:E46) -> 0.15
D31: Y2 | E31: =SUM(E35:E58) -> 0.26
D32: Y3 | E32: =SUM(E35:E70) -> 0.356
D33: Y4 | E33: =SUM(E35:E82) -> 0.446
I34: car depr. Value | J34: Loan OB
D35: 1 | E35: 0.02 | H35: =+E35 -> 0.02 | I35: =+$E$29*(100%-H35) -> 24500 | J35: 19673.323
D36: 2 | E36: 0.02 | H36: =+H35+E36 -> 0.04 | I36: =+$E$29*(100%-H36) -> 24000 | J36: 19343.38
D37: 3 | E37: 0.02 | H37: =+H36+E37 -> 0.06 | I37: =+$E$29*(100%-H37) -> 23500 | J37: 19010.137
D38: 4 | E38: 0.01 | H38: =+H37+E38 -> 0.07 | I38: =+$E$29*(100%-H38) -> 23250 | J38: 18673.562
D39: 5 | E39: 0.01 | H39: =+H38+E39 -> 0.08 | I39: =+$E$29*(100%-H39) -> 23000 | J39: 18333.62
D40: 6 | E40: 0.01 | H40: =+H39+E40 -> 0.09 | I40: =+$E$29*(100%-H40) -> 22750 | J40: 17990.28
D41: 7 | E41: 0.01 | H41: =+H40+E41 -> 0.1 | I41: =+$E$29*(100%-H41) -> 22500 | J41: 17643.506
D42: 8 | E42: 0.01 | H42: =+H41+E42 -> 0.11 | I42: =+$E$29*(100%-H42) -> 22250 | J42: 17293.264
D43: 9 | E43: 0.01 | H43: =+H42+E43 -> 0.12 | I43: =+$E$29*(100%-H43) -> 22000 | J43: 16939.52
D44: 10 | E44: 0.01 | H44: =+H43+E44 -> 0.13 | I44: =+$E$29*(100%-H44) -> 21750 | J44: 16582.239
D45: 11 | E45: 0.01 | H45: =+H44+E45 -> 0.14 | I45: =+$E$29*(100%-H45) -> 21500 | J45: 16221.385
D46: 12 | E46: 0.01 | H46: =+H45+E46 -> 0.15 | I46: =+$E$29*(100%-H46) -> 21250 | J46: 15856.922
D47: 13 | E47: 0.01 | H47: =+H46+E47 -> 0.16 | I47: =+$E$29*(100%-H47) -> 21000 | J47: 15488.814
...

Sheet Copyright-2
A40: Need help? Please see this page for information:
A41: https://exceltemplate.net/support/
